Workbook

Sheet CompanyDashboard
B3: Company Name: | D3: A&S Engineers, Inc. | I3: RG Dashboard Proof-of-Concept
C6: Company Overview | G6: Willing to Sponsor? | J6: Hiring (since 2022)
C7: Type: | D7: {=INDEX(CompanyList!B:B, MATCH(D3, CompanyList!A:A, 0))} -> Private | G7: {=INDEX(CompanyList!R:R, MATCH($D$3, CompanyList!A:A, 0))} -> Yes | J7: Bachelors | K7: {=INDEX(CompanyList!O:O, MATCH($D$3, CompanyList!A:A, 0))} -> #VALUE!
C8: 2025 Rev | D8: {=INDEX(CompanyList!C:C, MATCH($D$3, CompanyList!A:A, 0))} | E8: M $USD | J8: Masters | K8: {=INDEX(CompanyList!P:P, MATCH($D$3, CompanyList!A:A, 0))} -> #VALUE!
C9: Market Cap | D9: {=INDEX(CompanyList!E:E, MATCH($D$3, CompanyList!A:A, 0))} | E9: B $USD | J9: Doctorate | K9: {=INDEX(CompanyList!Q:Q, MATCH($D$3, CompanyList!A:A, 0))} -> #VALUE!
C10: # Emp | D10: {=INDEX(CompanyList!D:D, MATCH($D$3, CompanyList!A:A, 0))}
J11: Target Majors
J12: WIP
C13: Yearly Overview
D14: S24 | E14: F24 | F14: S25 | G14: F25 | H14: S26
C15: Attended CF? | D15: {=INDEX(CompanyList!AA:AA, MATCH($D$3, CompanyList!A:A, 0))} -> Yes | E15: {=INDEX(CompanyList!Y:Y, MATCH($D$3, CompanyList!$A:$A, 0))} -> Yes | F15: {=INDEX(CompanyList!W:W, MATCH($D$3, CompanyList!$A:$A, 0))} -> Yes | G15: {=INDEX(CompanyList!U:U, MATCH($D$3, CompanyList!$A:$A, 0))} -> Yes | H15: {=INDEX(CompanyList!S:S, MATCH($D$3, CompanyList!$A:$A, 0))} -> Yes
C16: Package | D16: {=INDEX(CompanyList!AB:AB, MATCH($D$3, CompanyList!A:A, 0))} -> Basic Two-Day [$2000.00] | E16: {=INDEX(CompanyList!Z:Z, MATCH($D$3, CompanyList!$A:$A, 0))} -> Basic One-Day: Thursday, September 5th [$1000.00] | F16: {=INDEX(CompanyList!X:X, MATCH($D$3, CompanyList!$A:$A, 0))} -> Basic One-Day: Thursday, January 23rd [$1000.00] | G16: {=INDEX(CompanyList!V:V, MATCH($D$3, CompanyList!$A:$A, 0))} -> Basic One-Day: Thursday, September 11th [$1000.00] | H16: {=INDEX(CompanyList!T:T, MATCH($D$3, CompanyList!$A:$A, 0))} -> Basic Two-Day [$2000.00]
C17: # Hired | D17: {=INDEX(CompanyList!J:J, MATCH($D$3, CompanyList!A:A, 0))} -> 0 | E17: {=INDEX(CompanyList!I:I, MATCH($D$3, CompanyList!$A:$A, 0))} -> 0 | F17: {=INDEX(CompanyList!H:H, MATCH($D$3, CompanyList!$A:$A, 0))} -> 0 | G17: {=INDEX(CompanyList!G:G, MATCH($D$3, CompanyList!$A:$A, 0))} -> 0 | H17: {=INDEX(CompanyList!F:F, MATCH($D$3, CompanyList!$A:$A, 0))} -> 0

Sheet CompanyList
A1: Company Name | B1: Type | C1: 2025 Revenue (M USD) | D1: 2025 Employees | E1: Market Cap (Billion USD) | F1: S26 Hiring | G1: F25 Hiring | H1: S25 Hiring | I1: F24 Hiring | J1: S24 Hiring | K1: F23 Hiring | L1: S23 Hiring | M1: F22 Hiring | N1: S22 Hiring | O1: Bachelor | P1: Master | Q1: Doctorate | R1: Willing to Sponsor? | S1: Attended S26? | T1: Package, S26 | U1: Attended F25? | V1: Package, F25 | W1: Attended S25? | X1: Package, S25 | Y1: Attended F24? | Z1: Package, F24 | AA1: Attended S24? | AB1: Package, S24
A2: A&S Engineers, Inc. | B2: Private | F2: =COUNTIF(S26_Emp!$C:$C,"*" &A2 & "*") -> 0 | G2: =COUNTIF(F25_Emp!$C:$C,"*" &A2 & "*") -> 0 | H2: =COUNTIF(S25_Emp!$C:$C,"*" & A2 & "*") -> 0 | I2: =COUNTIF(F24_Emp!$C:$C,"*" & $A2 & "*") -> 0 | J2: =COUNTIF(S24_Emp!$C:$C,"*" & $A2 & "*") -> 0 | K2: =COUNTIF(F23_Emp!$C:$C,"*" & $A2 & "*") -> 0 | L2: =COUNTIF(S23_Emp!$C:$C,"*" & $A2 & "*") -> 0 | M2: =COUNTIF(F22_Emp!$C:$C,"*" & $A2 & "*") -> 0 | N2: =COUNTIF(S22_Emp!$C:$C,"*" & $A2 & "*") -> 0 | O2: =COUNTIFS(S22_Emp!$C:$C,"*" & $A2 & "*", S22_S25_Emp!$B:$B, "Bachelor") -> #VALUE! | P2: =COUNTIFS(S22_Emp!$C:$C,"*" & $A2 & "*", S22_S25_Emp!$B:$B, "Master") -> #VALUE! | Q2: =COUNTIFS(S22_Emp!$C:$C,"*" & $A2 & "*", S22_S25_Emp!$B:$B, "Doctorate") -> #VALUE! | R2: {=IF(OR(INDEX(S26_CF!X:X, MATCH("*" & $A2 & "*", CompanyList!A:A, 0))=TRUE, INDEX(F25_CF!P:P, MATCH("*" & $A2 & "*", CompanyList!A:A, 0))=TRUE, INDEX(S25_CF!T:T, MATCH("*" & $A2 & "*", CompanyList!A:A, 0))=TRUE, INDEX(S24_CF!W:W, MATCH("*" & $A2 & "*", CompanyList!A:A, 0))=TRUE), "Yes", "No")} -> Yes | S2: =IF(COUNTIF(S26_CF!$A:$A,"*" & $A2 & "*") <> 0, "Yes", "No") -> Yes | T2: {=INDEX(S26_CF!K:K, MATCH("*" & $A2 & "*", S26_CF!A:A, 0))} -> Basic Two-Day [$2000.00] | U2: =IF(COUNTIF(F25_CF!$A:$A,"*" & $A2 & "*") <> 0, "Yes", "No") -> Yes | V2: {=INDEX(F25_CF!I:I, MATCH("*" & $A2 & "*", F25_CF!$A:$A, 0))} -> Basic One-Day: Thursday, September 11th [$1000.00] | W2: =IF(COUNTIF(S25_CF!$A:$A,"*" & $A2 & "*") <> 0, "Yes", "No") -> Yes | X2: {=INDEX(S25_CF!J:J, MATCH("*" & $A2 & "*", S25_CF!$A:$A, 0))} -> Basic One-Day: Thursday, January 23rd [$1000.00] | Y2: =IF(COUNTIF(F24_CF!$A:$A,"*" & $A2 & "*") <> 0, "Yes", "No") -> Yes | Z2: {=INDEX(F24_CF!N:N, MATCH("*" & $A2 & "*", F24_CF!$A:$A, 0))} -> Basic One-Day: Thursday, September 5th [$1000.00] | AA2: =IF(COUNTIF(S24_CF!$A:$A,"*" & $A2 & "*") <> 0, "Yes", "No") -> Yes | AB2: {=INDEX(S24_CF!H:H, MATCH("*" & $A2 & "*", S24_CF!$A:$A, 0))} -> Basic Two-Day [$2000.00]
A3: ABB Inc. | B3: Public | C3: 32000 | D3: 105000 | E3: 100 | F3: =COUNTIF(S26_Emp!$C:$C,"*" &A3 & "*") -> 0 | G3: =COUNTIF(F25_Emp!$C:$C,"*" &#REF! & "*") -> 0 | H3: =COUNTIF(S25_Emp!$C:$C,"*" & A3 & "*") -> 0 | I3: =COUNTIF(F24_Emp!$C:$C,"*" & B3 & "*") -> 1 | J3: =COUNTIF(S24_Emp!$C:$C,"*" & $A3 & "*") -> 1 | K3: =COUNTIF(F23_Emp!$C:$C,"*" & $A3 & "*") -> 0 | L3: =COUNTIF(S23_Emp!$C:$C,"*" & $A3 & "*") -> 0 | M3: =COUNTIF(F22_Emp!$C:$C,"*" & $A3 & "*") -> 0 | N3: =COUNTIF(S22_Emp!$C:$C,"*" & $A3 & "*") -> 0 | O3: =COUNTIFS(S22_Emp!$C:$C,"*" & $A3 & "*", S22_S25_Emp!$B:$B, "Bachelor") -> #VALUE! | P3: =COUNTIFS(S22_Emp!$C:$C,"*" & $A3 & "*", S22_S25_Emp!$B:$B, "Master") -> #VALUE! | Q3: =COUNTIFS(S22_Emp!$C:$C,"*" & $A3 & "*", S22_S25_Emp!$B:$B, "Doctorate") -> #VALUE! | R3: {=IF(OR(INDEX(S26_CF!X:X, MATCH("*" & $A3 & "*", CompanyList!A:A, 0))=TRUE, INDEX(F25_CF!P:P, MATCH("*" & $A3 & "*", CompanyList!A:A, 0))=TRUE, INDEX(S25_CF!T:T, MATCH("*" & $A3 & "*", CompanyList!A:A, 0))=TRUE, INDEX(S24_CF!W:W, MATCH("*" & $A3 & "*", CompanyList!A:A, 0))=TRUE), "Yes", "No")} -> No | S3: =IF(COUNTIF(S26_CF!$A:$A,"*" & $A3 & "*") <> 0, "Yes", "No") -> Yes | T3: {=INDEX(S26_CF!K:K, MATCH("*" & $A3 & "*", S26_CF!A:A, 0))} -> Gold One-Day: Wednesday, January 28th [$2500.00] | U3: =IF(COUNTIF(F25_CF!$A:$A,"*" & $A3 & "*") <> 0, "Yes", "No") -> Yes | V3: {=INDEX(F25_CF!I:I, MATCH("*" & $A3 & "*", F25_CF!$A:$A, 0))} -> Gold One-Day: Wednesday, September 10th [$2500.00] | W3: =IF(COUNTIF(S25_CF!$A:$A,"*" & $A3 & "*") <> 0, "Yes", "No") -> No | X3: {=INDEX(S25_CF!J:J, MATCH("*" & $A3 & "*", S25_CF!$A:$A, 0))} -> #N/A | Y3: =IF(COUNTIF(F24_CF!$A:$A,"*" & $A3 & "*") <> 0, "Yes", "No") -> Yes | Z3: {=INDEX(F24_CF!N:N, MATCH("*" & $A3 & "*", F24_CF!$A:$A, 0))} -> Gold One-Day: Wednesday, September 4th [$2500.00] | AA3: =IF(COUNTIF(S24_CF!$A:$A,"*" & $A3 & "*") <> 0, "Yes", "No") -> Yes | AB3: {=INDEX(S24_CF!H:H, MATCH("*" & $A3 & "*", S24_CF!$A:$A, 0))} -> Basic One-Day [$1000.00]
A4: AG&E | B4: Private | F4: =COUNTIF(S26_Emp!$C:$C,"*" &A4 & "*") -> 0 | G4: =COUNTIF(F25_Emp!$C:$C,"*" &#REF! & "*") -> 0 | H4: =COUNTIF(S25_Emp!$C:$C,"*" & A4 & "*") -> 0 | I4: =COUNTIF(F24_Emp!$C:$C,"*" & B4 & "*") -> 0 | J4: =COUNTIF(S24_Emp!$C:$C,"*" & $A4 & "*") -> 0 | K4: =COUNTIF(F23_Emp!$C:$C,"*" & $A4 & "*") -> 1 | L4: =COUNTIF(S23_Emp!$C:$C,"*" & $A4 & "*") -> 1 | M4: =COUNTIF(F22_Emp!$C:$C,"*" & $A4 & "*") -> 0 | N4: =COUNTIF(S22_Emp!$C:$C,"*" & $A4 & "*") -> 0 | O4: =COUNTIFS(S22_Emp!$C:$C,"*" & $A4 & "*", S22_S25_Emp!$B:$B, "Bachelor") -> #VALUE! | P4: =COUNTIFS(S22_Emp!$C:$C,"*" & $A4 & "*", S22_S25_Emp!$B:$B, "Master") -> #VALUE! | Q4: =COUNTIFS(S22_Emp!$C:$C,"*" & $A4 & "*", S22_S25_Emp!$B:$B, "Doctorate") -> #VALUE! | R4: {=IF(OR(INDEX(S26_CF!X:X, MATCH("*" & $A4 & "*", CompanyList!A:A, 0))=TRUE, INDEX(F25_CF!P:P, MATCH("*" & $A4 & "*", CompanyList!A:A, 0))=TRUE, INDEX(S25_CF!T:T, MATCH("*" & $A4 & "*", CompanyList!A:A, 0))=TRUE, INDEX(S24_CF!W:W, MATCH("*" & $A4 & "*", CompanyList!A:A, 0))=TRUE), "Yes", "No")} -> Yes | S4: =IF(COUNTIF(S26_CF!$A:$A,"*" & $A4 & "*") <> 0, "Yes", "No") -> Yes | T4: {=INDEX(S26_CF!K:K, MATCH("*" & $A4 & "*", S26_CF!A:A, 0))} -> Basic One-Day: Wednesday, January 28th [$1000.00] | U4: =IF(COUNTIF(F25_CF!$A:$A,"*" & $A4 & "*") <> 0, "Yes", "No") -> No | V4: {=INDEX(F25_CF!I:I, MATCH("*" & $A4 & "*", F25_CF!$A:$A, 0))} -> #N/A | W4: =IF(COUNTIF(S25_CF!$A:$A,"*" & $A4 & "*") <> 0, "Yes", "No") -> Yes | X4: {=INDEX(S25_CF!J:J, MATCH("*" & $A4 & "*", S25_CF!$A:$A, 0))} -> Basic One-Day: Wednesday, January 22nd [$1000.00] | Y4: =IF(COUNTIF(F24_CF!$A:$A,"*" & $A4 & "*") <> 0, "Yes", "No") -> No | Z4: {=INDEX(F24_CF!N:N, MATCH("*" & $A4 & "*", F24_CF!$A:$A, 0))} -> #N/A | AA4: =IF(COUNTIF(S24_CF!$A:$A,"*" & $A4 & "*") <> 0, "Yes", "No") -> Yes | AB4: {=INDEX(S24_CF!H:H, MATCH("*" & $A4 & "*", S24_CF!$A:$A, 0))} -> Basic Two-Day [$2000.00]
A5: Aguirre & Fields LP | B5: Private | F5: =COUNTIF(S26_Emp!$C:$C,"*" &A5 & "*") -> 0 | G5: =COUNTIF(F25_Emp!$C:$C,"*" &#REF! & "*") -> 0 | H5: =COUNTIF(S25_Emp!$C:$C,"*" & A5 & "*") -> 0 | I5: =COUNTIF(F24_Emp!$C:$C,"*" & B5 & "*") -> 0 | J5: =COUNTIF(S24_Emp!$C:$C,"*" & $A5 & "*") -> 0 | K5: =COUNTIF(F23_Emp!$C:$C,"*" & $A5 & "*") -> 0 | L5: =COUNTIF(S23_Emp!$C:$C,"*" & $A5 & "*") -> 1 | M5: =COUNTIF(F22_Emp!$C:$C,"*" & $A5 & "*") -> 0 | N5: =COUNTIF(S22_Emp!$C:$C,"*" & $A5 & "*") -> 0 | O5: =COUNTIFS(S22_Emp!$C:$C,"*" & $A5 & "*", S22_S25_Emp!$B:$B, "Bachelor") -> #VALUE! | P5: =COUNTIFS(S22_Emp!$C:$C,"*" & $A5 & "*", S22_S25_Emp!$B:$B, "Master") -> #VALUE! | Q5: =COUNTIFS(S22_Emp!$C:$C,"*" & $A5 & "*", S22_S25_Emp!$B:$B, "Doctorate") -> #VALUE! | R5: {=IF(OR(INDEX(S26_CF!X:X, MATCH("*" & $A5 & "*", CompanyList!A:A, 0))=TRUE, INDEX(F25_CF!P:P, MATCH("*" & $A5 & "*", CompanyList!A:A, 0))=TRUE, INDEX(S25_CF!T:T, MATCH("*" & $A5 & "*", CompanyList!A:A, 0))=TRUE, INDEX(S24_CF!W:W, MATCH("*" & $A5 & "*", CompanyList!A:A, 0))=TRUE), "Yes", "No")} -> No | S5: =IF(COUNTIF(S26_CF!$A:$A,"*" & $A5 & "*") <> 0, "Yes", "No") -> Yes | T5: {=INDEX(S26_CF!K:K, MATCH("*" & $A5 & "*", S26_CF!A:A, 0))} -> Basic One-Day: Wednesday, January 28th [$1000.00] | U5: =IF(COUNTIF(F25_CF!$A:$A,"*" & $A5 & "*") <> 0, "Yes", "No") -> No | V5: {=INDEX(F25_CF!I:I, MATCH("*" & $A5 & "*", F25_CF!$A:$A, 0))} -> #N/A | W5: =IF(COUNTIF(S25_CF!$A:$A,"*" & $A5 & "*") <> 0, "Yes", "No") -> Yes | X5: {=INDEX(S25_CF!J:J, MATCH("*" & $A5 & "*", S25_CF!$A:$A, 0))} -> Basic One-Day: Thursday, January 23rd [$1000.00] | Y5: =IF(COUNTIF(F24_CF!$A:$A,"*" & $A5 & "*") <> 0, "Yes", "No") -> Yes | Z5: {=INDEX(F24_CF!N:N, MATCH("*" & $A5 & "*", F24_CF!$A:$A, 0))} -> Basic One-Day: Thursday, September 5th [$1000.00] | AA5: =IF(COUNTIF(S24_CF!$A:$A,"*" & $A5 & "*") <> 0, "Yes", "No") -> Yes | AB5: {=INDEX(S24_CF!H:H, MATCH("*" & $A5 & "*", S24_CF!$A:$A, 0))} -> Silver One-Day [$1800.00]
A6: Air Liquide | B6: Public | C6: 29500 | D6: 67000 | E6: 101 | F6: =COUNTIF(S26_Emp!$C:$C,"*" &A6 & "*") -> 0 | G6: =COUNTIF(F25_Emp!$C:$C,"*" &#REF! & "*") -> 0 | H6: =COUNTIF(S25_Emp!$C:$C,"*" & A6 & "*") -> 1 | I6: =COUNTIF(F24_Emp!$C:$C,"*" & B6 & "*") -> 1 | J6: =COUNTIF(S24_Emp!$C:$C,"*" & $A6 & "*") -> 2 | K6: =COUNTIF(F23_Emp!$C:$C,"*" & $A6 & "*") -> 1 | L6: =COUNTIF(S23_Emp!$C:$C,"*" & $A6 & "*") -> 1 | M6: =COUNTIF(F22_Emp!$C:$C,"*" & $A6 & "*") -> 1 | N6: =COUNTIF(S22_Emp!$C:$C,"*" & $A6 & "*") -> 1 | O6: =COUNTIFS(S22_Emp!$C:$C,"*" & $A6 & "*", S22_S25_Emp!$B:$B, "Bachelor") -> #VALUE! | P6: =COUNTIFS(S22_Emp!$C:$C,"*" & $A6 & "*", S22_S25_Emp!$B:$B, "Master") -> #VALUE! | Q6: =COUNTIFS(S22_Emp!$C:$C,"*" & $A6 & "*", S22_S25_Emp!$B:$B, "Doctorate") -> #VALUE! | R6: {=IF(OR(INDEX(S26_CF!X:X, MATCH("*" & $A6 & "*", CompanyList!A:A, 0))=TRUE, INDEX(F25_CF!P:P, MATCH("*" & $A6 & "*", CompanyList!A:A, 0))=TRUE, INDEX(S25_CF!T:T, MATCH("*" & $A6 & "*", CompanyList!A:A, 0))=TRUE, INDEX(S24_CF!W:W, MATCH("*" & $A6 & "*", CompanyList!A:A, 0))=TRUE), "Yes", "No")} -> No | S6: =IF(COUNTIF(S26_CF!$A:$A,"*" & $A6 & "*") <> 0, "Yes", "No") -> Yes | T6: {=INDEX(S26_CF!K:K, MATCH("*" & $A6 & "*", S26_CF!A:A, 0))} -> Basic One-Day: Wednesday, January 28th [$1000.00] | U6: =IF(COUNTIF(F25_CF!$A:$A,"*" & $A6 & "*") <> 0, "Yes", "No") -> Yes | V6: {=INDEX(F25_CF!I:I, MATCH("*" & $A6 & "*", F25_CF!$A:$A, 0))} -> Basic One-Day: Wednesday, September 10th [$1000.00] | W6: =IF(COUNTIF(S25_CF!$A:$A,"*" & $A6 & "*") <> 0, "Yes", "No") -> Yes | X6: {=INDEX(S25_CF!J:J, MATCH("*" & $A6 & "*", S25_CF!$A:$A, 0))} -> Basic One-Day: Thursday, January 23rd [$1000.00] | Y6: =IF(COUNTIF(F24_CF!$A:$A,"*" & $A6 & "*") <> 0, "Yes", "No") -> Yes | Z6: {=INDEX(F24_CF!N:N, MATCH("*" & $A6 & "*", F24_CF!$A:$A, 0))} -> Basic One-Day: Wednesday, September 4th [$1000.00] | AA6: =IF(COUNTIF(S24_CF!$A:$A,"*" & $A6 & "*") <> 0, "Yes", "No") -> Yes | AB6: {=INDEX(S24_CF!H:H, MATCH("*" & $A6 & "*", S24_CF!$A:$A, 0))} -> Basic One-Day [$1000.00]
A7: Albers Aerospace | B7: Private | F7: =COUNTIF(S26_Emp!$C:$C,"*" &A7 & "*") -> 0 | G7: =COUNTIF(F25_Emp!$C:$C,"*" &#REF! & "*") -> 0 | H7: =COUNTIF(S25_Emp!$C:$C,"*" & A7 & "*") -> 0 | I7: =COUNTIF(F24_Emp!$C:$C,"*" & B7 & "*") -> 0 | J7: =COUNTIF(S24_Emp!$C:$C,"*" & $A7 & "*") -> 0 | K7: =COUNTIF(F23_Emp!$C:$C,"*" & $A7 & "*") -> 0 | L7: =COUNTIF(S23_Emp!$C:$C,"*" & $A7 & "*") -> 2 | M7: =COUNTIF(F22_Emp!$C:$C,"*" & $A7 & "*") -> 0 | N7: =COUNTIF(S22_Emp!$C:$C,"*" & $A7 & "*") -> 2 | O7: =COUNTIFS(S22_Emp!$C:$C,"*" & $A7 & "*", S22_S25_Emp!$B:$B, "Bachelor") -> #VALUE! | P7: =COUNTIFS(S22_Emp!$C:$C,"*" & $A7 & "*", S22_S25_Emp!$B:$B, "Master") -> #VALUE! | Q7: =COUNTIFS(S22_Emp!$C:$C,"*" & $A7 & "*", S22_S25_Emp!$B:$B, "Doctorate") -> #VALUE! | R7: {=IF(OR(INDEX(S26_CF!X:X, MATCH("*" & $A7 & "*", CompanyList!A:A, 0))=TRUE, INDEX(F25_CF!P:P, MATCH("*" & $A7 & "*", CompanyList!A:A, 0))=TRUE, INDEX(S25_CF!T:T, MATCH("*" & $A7 & "*", CompanyList!A:A, 0))=TRUE, INDEX(S24_CF!W:W, MATCH("*" & $A7 & "*", CompanyList!A:A, 0))=TRUE), "Yes", "No")} -> No | S7: =IF(COUNTIF(S26_CF!$A:$A,"*" & $A7 & "*") <> 0, "Yes", "No") -> No | T7: {=INDEX(S26_CF!K:K, MATCH("*" & $A7 & "*", S26_CF!A:A, 0))} -> #N/A | U7: =IF(COUNTIF(F25_CF!$A:$A,"*" & $A7 & "*") <> 0, "Yes", "No") -> Yes | V7: {=INDEX(F25_CF!I:I, MATCH("*" & $A7 & "*", F25_CF!$A:$A, 0))} -> Basic Two-Day [$2000.00] | W7: =IF(COUNTIF(S25_CF!$A:$A,"*" & $A7 & "*") <> 0, "Yes", "No") -> Yes | X7: {=INDEX(S25_CF!J:J, MATCH("*" & $A7 & "*", S25_CF!$A:$A, 0))} -> Basic One-Day: Thursday, January 23rd [$1000.00] | Y7: =IF(COUNTIF(F24_CF!$A:$A,"*" & $A7 & "*") <> 0, "Yes", "No") -> Yes | Z7: {=INDEX(F24_CF!N:N, MATCH("*" & $A7 & "*", F24_CF!$A:$A, 0))} -> Basic Two-Day [$2000.00] | AA7: =IF(COUNTIF(S24_CF!$A:$A,"*" & $A7 & "*") <> 0, "Yes", "No") -> Yes | AB7: {=INDEX(S24_CF!H:H, MATCH("*" & $A7 & "*", S24_CF!$A:$A, 0))} -> Basic Two-Day [$2000.00]
A8: ALL4 LLC | B8: Private | F8: =COUNTIF(S26_Emp!$C:$C,"*" &A8 & "*") -> 0 | G8: =COUNTIF(F25_Emp!$C:$C,"*" &#REF! & "*") -> 0 | H8: =COUNTIF(S25_Emp!$C:$C,"*" & A8 & "*") -> 0 | I8: =COUNTIF(F24_Emp!$C:$C,"*" & B8 & "*") -> 0 | J8: =COUNTIF(S24_Emp!$C:$C,"*" & $A8 & "*") -> 0 | K8: =COUNTIF(F23_Emp!$C:$C,"*" & $A8 & "*") -> 0 | L8: =COUNTIF(S23_Emp!$C:$C,"*" & $A8 & "*") -> 0 | M8: =COUNTIF(F22_Emp!$C:$C,"*" & $A8 & "*") -> 0 | N8: =COUNTIF(S22_Emp!$C:$C,"*" & $A8 & "*") -> 0 | O8: =COUNTIFS(S22_Emp!$C:$C,"*" & $A8 & "*", S22_S25_Emp!$B:$B, "Bachelor") -> #VALUE! | P8: =COUNTIFS(S22_Emp!$C:$C,"*" & $A8 & "*", S22_S25_Emp!$B:$B, "Master") -> #VALUE! | Q8: =COUNTIFS(S22_Emp!$C:$C,"*" & $A8 & "*", S22_S25_Emp!$B:$B, "Doctorate") -> #VALUE! | R8: {=IF(OR(INDEX(S26_CF!X:X, MATCH("*" & $A8 & "*", CompanyList!A:A, 0))=TRUE, INDEX(F25_CF!P:P, MATCH("*" & $A8 & "*", CompanyList!A:A, 0))=TRUE, INDEX(S25_CF!T:T, MATCH("*" & $A8 & "*", CompanyList!A:A, 0))=TRUE, INDEX(S24_CF!W:W, MATCH("*" & $A8 & "*", CompanyList!A:A, 0))=TRUE), "Yes", "No")} -> No | S8: =IF(COUNTIF(S26_CF!$A:$A,"*" & $A8 & "*") <> 0, "Yes", "No") -> No | T8: {=INDEX(S26_CF!K:K, MATCH("*" & $A8 & "*", S26_CF!A:A, 0))} -> #N/A | U8: =IF(COUNTIF(F25_CF!$A:$A,"*" & $A8 & "*") <> 0, "Yes", "No") -> No | V8: {=INDEX(F25_CF!I:I, MATCH("*" & $A8 & "*", F25_CF!$A:$A, 0))} -> #N/A | W8: =IF(COUNTIF(S25_CF!$A:$A,"*" & $A8 & "*") <> 0, "Yes", "No") -> Yes | X8: {=INDEX(S25_CF!J:J, MATCH("*" & $A8 & "*", S25_CF!$A:$A, 0))} -> Basic One-Day: Wednesday, January 22nd [$1000.00] | Y8: =IF(COUNTIF(F24_CF!$A:$A,"*" & $A8 & "*") <> 0, "Yes", "No") -> Yes | Z8: {=INDEX(F24_CF!N:N, MATCH("*" & $A8 & "*", F24_CF!$A:$A, 0))} -> Basic One-Day: Thursday, September 5th [$1000.00] | AA8: =IF(COUNTIF(S24_CF!$A:$A,"*" & $A8 & "*") <> 0, "Yes", "No") -> Yes | AB8: {=INDEX(S24_CF!H:H, MATCH("*" & $A8 & "*", S24_CF!$A:$A, 0))} -> Basic One-Day [$1000.00]
A9: America's Navy | B9: Government | D9: 330000 | F9: =COUNTIF(S26_Emp!$C:$C,"*" &A9 & "*") -> 0 | G9: =COUNTIF(F25_Emp!$C:$C,"*" &#REF! & "*") -> 0 | H9: =COUNTIF(S25_Emp!$C:$C,"*" & A9 & "*") -> 0 | I9: =COUNTIF(F24_Emp!$C:$C,"*" & B9 & "*") -> 0 | J9: =COUNTIF(S24_Emp!$C:$C,"*" & $A9 & "*") -> 1 | K9: =COUNTIF(F23_Emp!$C:$C,"*" & $A9 & "*") -> 0 | L9: =COUNTIF(S23_Emp!$C:$C,"*" & $A9 & "*") -> 0 | M9: =COUNTIF(F22_Emp!$C:$C,"*" & $A9 & "*") -> 0 | N9: =COUNTIF(S22_Emp!$C:$C,"*" & $A9 & "*") -> 0 | O9: =COUNTIFS(S22_Emp!$C:$C,"*" & $A9 & "*", S22_S25_Emp!$B:$B, "Bachelor") -> #VALUE! | P9: =COUNTIFS(S22_Emp!$C:$C,"*" & $A9 & "*", S22_S25_Emp!$B:$B, "Master") -> #VALUE! | Q9: =COUNTIFS(S22_Emp!$C:$C,"*" & $A9 & "*", S22_S25_Emp!$B:$B, "Doctorate") -> #VALUE! | R9: {=IF(OR(INDEX(S26_CF!X:X, MATCH("*" & $A9 & "*", CompanyList!A:A, 0))=TRUE, INDEX(F25_CF!P:P, MATCH("*" & $A9 & "*", CompanyList!A:A, 0))=TRUE, INDEX(S25_CF!T:T, MATCH("*" & $A9 & "*", CompanyList!A:A, 0))=TRUE, INDEX(S24_CF!W:W, MATCH("*" & $A9 & "*", CompanyList!A:A, 0))=TRUE), "Yes", "No")} -> No | S9: =IF(COUNTIF(S26_CF!$A:$A,"*" & $A9 & "*") <> 0, "Yes", "No") -> No | T9: {=INDEX(S26_CF!K:K, MATCH("*" & $A9 & "*", S26_CF!A:A, 0))} -> #N/A | U9: =IF(COUNTIF(F25_CF!$A:$A,"*" & $A9 & "*") <> 0, "Yes", "No") -> No | V9: {=INDEX(F25_CF!I:I, MATCH("*" & $A9 & "*", F25_CF!$A:$A, 0))} -> #N/A | W9: =IF(COUNTIF(S25_CF!$A:$A,"*" & $A9 & "*") <> 0, "Yes", "No") -> No | X9: {=INDEX(S25_CF!J:J, MATCH("*" & $A9 & "*", S25_CF!$A:$A, 0))} -> #N/A | Y9: =IF(COUNTIF(F24_CF!$A:$A,"*" & $A9 & "*") <> 0, "Yes", "No") -> Yes | Z9: {=INDEX(F24_CF!N:N, MATCH("*" & $A9 & "*", F24_CF!$A:$A, 0))} -> Basic Two-Day [$2000.00] | AA9: =IF(COUNTIF(S24_CF!$A:$A,"*" & $A9 & "*") <> 0, "Yes", "No") -> Yes | AB9: {=INDEX(S24_CF!H:H, MATCH("*" & $A9 & "*", S24_CF!$A:$A, 0))} -> Basic Two-Day [$2000.00]
A10: Andersen Corporation | B10: Private | C10: 3500 | D10: 13000 | F10: =COUNTIF(S26_Emp!$C:$C,"*" &A10 & "*") -> 0 | G10: =COUNTIF(F25_Emp!$C:$C,"*" &#REF! & "*") -> 0 | H10: =COUNTIF(S25_Emp!$C:$C,"*" & A10 & "*") -> 0 | I10: =COUNTIF(F24_Emp!$C:$C,"*" & B10 & "*") -> 0 | J10: =COUNTIF(S24_Emp!$C:$C,"*" & $A10 & "*") -> 0 | K10: =COUNTIF(F23_Emp!$C:$C,"*" & $A10 & "*") -> 0 | L10: =COUNTIF(S23_Emp!$C:$C,"*" & $A10 & "*") -> 0 | M10: =COUNTIF(F22_Emp!$C:$C,"*" & $A10 & "*") -> 1 | N10: =COUNTIF(S22_Emp!$C:$C,"*" & $A10 & "*") -> 2 | O10: =COUNTIFS(S22_Emp!$C:$C,"*" & $A10 & "*", S22_S25_Emp!$B:$B, "Bachelor") -> #VALUE! | P10: =COUNTIFS(S22_Emp!$C:$C,"*" & $A10 & "*", S22_S25_Emp!$B:$B, "Master") -> #VALUE! | Q10: =COUNTIFS(S22_Emp!$C:$C,"*" & $A10 & "*", S22_S25_Emp!$B:$B, "Doctorate") -> #VALUE! | R10: {=IF(OR(INDEX(S26_CF!X:X, MATCH("*" & $A10 & "*", CompanyList!A:A, 0))=TRUE, INDEX(F25_CF!P:P, MATCH("*" & $A10 & "*", CompanyList!A:A, 0))=TRUE, INDEX(S25_CF!T:T, MATCH("*" & $A10 & "*", CompanyList!A:A, 0))=TRUE, INDEX(S24_CF!W:W, MATCH("*" & $A10 & "*", CompanyList!A:A, 0))=TRUE), "Yes", "No")} -> Yes | S10: =IF(COUNTIF(S26_CF!$A:$A,"*" & $A10 & "*") <> 0, "Yes", "No") -> Yes | T10: {=INDEX(S26_CF!K:K, MATCH("*" & $A10 & "*", S26_CF!A:A, 0))} -> Silver Two-Day [$3000.00] | U10: =IF(COUNTIF(F25_CF!$A:$A,"*" & $A10 & "*") <> 0, "Yes", "No") -> Yes | V10: {=INDEX(F25_CF!I:I, MATCH("*" & $A10 & "*", F25_CF!$A:$A, 0))} -> Silver Two-Day [$3000.00] | W10: =IF(COUNTIF(S25_CF!$A:$A,"*" & $A10 & "*") <> 0, "Yes", "No") -> Yes | X10: {=INDEX(S25_CF!J:J, MATCH("*" & $A10 & "*", S25_CF!$A:$A, 0))} -> Gold Two-Day [$5500.00] | Y10: =IF(COUNTIF(F24_CF!$A:$A,"*" & $A10 & "*") <> 0, "Yes", "No") -> Yes | Z10: {=INDEX(F24_CF!N:N, MATCH("*" & $A10 & "*", F24_CF!$A:$A, 0))} -> Gold Two-Day [$5500.00] | AA10: =IF(COUNTIF(S24_CF!$A:$A,"*" & $A10 & "*") <> 0, "Yes", "No") -> Yes | AB10: {=INDEX(S24_CF!H:H, MATCH("*" & $A10 & "*", S24_CF!$A:$A, 0))} -> Basic Two-Day [$2000.00]
A11: Applied Research Laboratories | B11: Government/Univ | D11: 1000 | F11: =COUNTIF(S26_Emp!$C:$C,"*" &A11 & "*") -> 0 | G11: =COUNTIF(F25_Emp!$C:$C,"*" &#REF! & "*") -> 0 | H11: =COUNTIF(S25_Emp!$C:$C,"*" & A11 & "*") -> 0 | I11: =COUNTIF(F24_Emp!$C:$C,"*" & B11 & "*") -> 0 | J11: =COUNTIF(S24_Emp!$C:$C,"*" & $A11 & "*") -> 0 | K11: =COUNTIF(F23_Emp!$C:$C,"*" & $A11 & "*") -> 0 | L11: =COUNTIF(S23_Emp!$C:$C,"*" & $A11 & "*") -> 1 | M11: =COUNTIF(F22_Emp!$C:$C,"*" & $A11 & "*") -> 0 | N11: =COUNTIF(S22_Emp!$C:$C,"*" & $A11 & "*") -> 0 | O11: =COUNTIFS(S22_Emp!$C:$C,"*" & $A11 & "*", S22_S25_Emp!$B:$B, "Bachelor") -> #VALUE! | P11: =COUNTIFS(S22_Emp!$C:$C,"*" & $A11 & "*", S22_S25_Emp!$B:$B, "Master") -> #VALUE! | Q11: =COUNTIFS(S22_Emp!$C:$C,"*" & $A11 & "*", S22_S25_Emp!$B:$B, "Doctorate") -> #VALUE! | R11: {=IF(OR(INDEX(S26_CF!X:X, MATCH("*" & $A11 & "*", CompanyList!A:A, 0))=TRUE, INDEX(F25_CF!P:P, MATCH("*" & $A11 & "*", CompanyList!A:A, 0))=TRUE, INDEX(S25_CF!T:T, MATCH("*" & $A11 & "*", CompanyList!A:A, 0))=TRUE, INDEX(S24_CF!W:W, MATCH("*" & $A11 & "*", CompanyList!A:A, 0))=TRUE), "Yes", "No")} -> No | S11: =IF(COUNTIF(S26_CF!$A:$A,"*" & $A11 & "*") <> 0, "Yes", "No") -> Yes | T11: {=INDEX(S26_CF!K:K, MATCH("*" & $A11 & "*", S26_CF!A:A, 0))} -> Gold Two-Day [$5500.00] | U11: =IF(COUNTIF(F25_CF!$A:$A,"*" & $A11 & "*") <> 0, "Yes", "No") -> Yes | V11: {=INDEX(F25_CF!I:I, MATCH("*" & $A11 & "*", F25_CF!$A:$A, 0))} -> Gold Two-Day [$5500.00] | W11: =IF(COUNTIF(S25_CF!$A:$A,"*" & $A11 & "*") <> 0, "Yes", "No") -> Yes | X11: {=INDEX(S25_CF!J:J, MATCH("*" & $A11 & "*", S25_CF!$A:$A, 0))} -> Gold Two-Day [$5500.00] | Y11: =IF(COUNTIF(F24_CF!$A:$A,"*" & $A11 & "*") <> 0, "Yes", "No") -> Yes | Z11: {=INDEX(F24_CF!N:N, MATCH("*" & $A11 & "*", F24_CF!$A:$A, 0))} -> Gold Two-Day [$5500.00] | AA11: =IF(COUNTIF(S24_CF!$A:$A,"*" & $A11 & "*") <> 0, "Yes", "No") -> Yes | AB11: {=INDEX(S24_CF!H:H, MATCH("*" & $A11 & "*", S24_CF!$A:$A, 0))} -> Gold Two-Day [$5000.00]
A12: Arbin Instruments | B12: Private | F12: =COUNTIF(S26_Emp!$C:$C,"*" &A12 & "*") -> 0 | G12: =COUNTIF(F25_Emp!$C:$C,"*" &#REF! & "*") -> 0 | H12: =COUNTIF(S25_Emp!$C:$C,"*" & A12 & "*") -> 0 | I12: =COUNTIF(F24_Emp!$C:$C,"*" & B12 & "*") -> 0 | J12: =COUNTIF(S24_Emp!$C:$C,"*" & $A12 & "*") -> 1 | K12: =COUNTIF(F23_Emp!$C:$C,"*" & $A12 & "*") -> 0 | L12: =COUNTIF(S23_Emp!$C:$C,"*" & $A12 & "*") -> 1 | M12: =COUNTIF(F22_Emp!$C:$C,"*" & $A12 & "*") -> 0 | N12: =COUNTIF(S22_Emp!$C:$C,"*" & $A12 & "*") -> 0 | O12: =COUNTIFS(S22_Emp!$C:$C,"*" & $A12 & "*", S22_S25_Emp!$B:$B, "Bachelor") -> #VALUE! | P12: =COUNTIFS(S22_Emp!$C:$C,"*" & $A12 & "*", S22_S25_Emp!$B:$B, "Master") -> #VALUE! | Q12: =COUNTIFS(S22_Emp!$C:$C,"*" & $A12 & "*", S22_S25_Emp!$B:$B, "Doctorate") -> #VALUE! | R12: {=IF(OR(INDEX(S26_CF!X:X, MATCH("*" & $A12 & "*", CompanyList!A:A, 0))=TRUE, INDEX(F25_CF!P:P, MATCH("*" & $A12 & "*", CompanyList!A:A, 0))=TRUE, INDEX(S25_CF!T:T, MATCH("*" & $A12 & "*", CompanyList!A:A, 0))=TRUE, INDEX(S24_CF!W:W, MATCH("*" & $A12 & "*", CompanyList!A:A, 0))=TRUE), "Yes", "No")} -> No | S12: =IF(COUNTIF(S26_CF!$A:$A,"*" & $A12 & "*") <> 0, "Yes", "No") -> No | T12: {=INDEX(S26_CF!K:K, MATCH("*" & $A12 & "*", S26_CF!A:A, 0))} -> #N/A | U12: =IF(COUNTIF(F25_CF!$A:$A,"*" & $A12 & "*") <> 0, "Yes", "No") -> No | V12: {=INDEX(F25_CF!I:I, MATCH("*" & $A12 & "*", F25_CF!$A:$A, 0))} -> #N/A | W12: =IF(COUNTIF(S25_CF!$A:$A,"*" & $A12 & "*") <> 0, "Yes", "No") -> Yes | X12: {=INDEX(S25_CF!J:J, MATCH("*" & $A12 & "*", S25_CF!$A:$A, 0))} -> Gold Two-Day [$5500.00] | Y12: =IF(COUNTIF(F24_CF!$A:$A,"*" & $A12 & "*") <> 0, "Yes", "No") -> Yes | Z12: {=INDEX(F24_CF!N:N, MATCH("*" & $A12 & "*", F24_CF!$A:$A, 0))} -> Gold Two-Day [$5500.00] | AA12: =IF(COUNTIF(S24_CF!$A:$A,"*" & $A12 & "*") <> 0, "Yes", "No") -> Yes | AB12: {=INDEX(S24_CF!H:H, MATCH("*" & $A12 & "*", S24_CF!$A:$A, 0))} -> Gold Two-Day [$5000.00]
A13: ARCO/Murray National Construction Company | B13: Private | F13: =COUNTIF(S26_Emp!$C:$C,"*" &A13 & "*") -> 0 | G13: =COUNTIF(F25_Emp!$C:$C,"*" &#REF! & "*") -> 0 | H13: =COUNTIF(S25_Emp!$C:$C,"*" & A13 & "*") -> 0 | I13: =COUNTIF(F24_Emp!$C:$C,"*" & B13 & "*") -> 0 | J13: =COUNTIF(S24_Emp!$C:$C,"*" & $A13 & "*") -> 1 | K13: =COUNTIF(F23_Emp!$C:$C,"*" & $A13 & "*") -> 0 | L13: =COUNTIF(S23_Emp!$C:$C,"*" & $A13 & "*") -> 0 | M13: =COUNTIF(F22_Emp!$C:$C,"*" & $A13 & "*") -> 0 | N13: =COUNTIF(S22_Emp!$C:$C,"*" & $A13 & "*") -> 0 | O13: =COUNTIFS(S22_Emp!$C:$C,"*" & $A13 & "*", S22_S25_Emp!$B:$B, "Bachelor") -> #VALUE! | P13: =COUNTIFS(S22_Emp!$C:$C,"*" & $A13 & "*", S22_S25_Emp!$B:$B, "Master") -> #VALUE! | Q13: =COUNTIFS(S22_Emp!$C:$C,"*" & $A13 & "*", S22_S25_Emp!$B:$B, "Doctorate") -> #VALUE! | R13: {=IF(OR(INDEX(S26_CF!X:X, MATCH("*" & $A13 & "*", CompanyList!A:A, 0))=TRUE, INDEX(F25_CF!P:P, MATCH("*" & $A13 & "*", CompanyList!A:A, 0))=TRUE, INDEX(S25_CF!T:T, MATCH("*" & $A13 & "*", CompanyList!A:A, 0))=TRUE, INDEX(S24_CF!W:W, MATCH("*" & $A13 & "*", CompanyList!A:A, 0))=TRUE), "Yes", "No")} -> No | S13: =IF(COUNTIF(S26_CF!$A:$A,"*" & $A13 & "*") <> 0, "Yes", "No") -> Yes | T13: {=INDEX(S26_CF!K:K, MATCH("*" & $A13 & "*", S26_CF!A:A, 0))} -> Basic Two-Day [$2000.00] | U13: =IF(COUNTIF(F25_CF!$A:$A,"*" & $A13 & "*") <> 0, "Yes", "No") -> Yes | V13: {=INDEX(F25_CF!I:I, MATCH("*" & $A13 & "*", F25_CF!$A:$A, 0))} -> Basic Two-Day [$2000.00] | W13: =IF(COUNTIF(S25_CF!$A:$A,"*" & $A13 & "*") <> 0, "Yes", "No") -> Yes | X13: {=INDEX(S25_CF!J:J, MATCH("*" & $A13 & "*", S25_CF!$A:$A, 0))} -> Basic Two-Day [$2000.00] | Y13: =IF(COUNTIF(F24_CF!$A:$A,"*" & $A13 & "*") <> 0, "Yes", "No") -> Yes | Z13: {=INDEX(F24_CF!N:N, MATCH("*" & $A13 & "*", F24_CF!$A:$A, 0))} -> Basic Two-Day [$2000.00] | AA13: =IF(COUNTIF(S24_CF!$A:$A,"*" & $A13 & "*") <> 0, "Yes", "No") -> Yes | AB13: {=INDEX(S24_CF!H:H, MATCH("*" & $A13 & "*", S24_CF!$A:$A, 0))} -> Basic Two-Day [$2000.00]
A14: Ardurra Group | B14: Private | F14: =COUNTIF(S26_Emp!$C:$C,"*" &A14 & "*") -> 0 | G14: =COUNTIF(F25_Emp!$C:$C,"*" &#REF! & "*") -> 0 | H14: =COUNTIF(S25_Emp!$C:$C,"*" & A14 & "*") -> 0 | I14: =COUNTIF(F24_Emp!$C:$C,"*" & B14 & "*") -> 0 | J14: =COUNTIF(S24_Emp!$C:$C,"*" & $A14 & "*") -> 0 | K14: =COUNTIF(F23_Emp!$C:$C,"*" & $A14 & "*") -> 0 | L14: =COUNTIF(S23_Emp!$C:$C,"*" & $A14 & "*") -> 0 | M14: =COUNTIF(F22_Emp!$C:$C,"*" & $A14 & "*") -> 0 | N14: =COUNTIF(S22_Emp!$C:$C,"*" & $A14 & "*") -> 0 | O14: =COUNTIFS(S22_Emp!$C:$C,"*" & $A14 & "*", S22_S25_Emp!$B:$B, "Bachelor") -> #VALUE! | P14: =COUNTIFS(S22_Emp!$C:$C,"*" & $A14 & "*", S22_S25_Emp!$B:$B, "Master") -> #VALUE! | Q14: =COUNTIFS(S22_Emp!$C:$C,"*" & $A14 & "*", S22_S25_Emp!$B:$B, "Doctorate") -> #VALUE! | R14: {=IF(OR(INDEX(S26_CF!X:X, MATCH("*" & $A14 & "*", CompanyList!A:A, 0))=TRUE, INDEX(F25_CF!P:P, MATCH("*" & $A14 & "*", CompanyList!A:A, 0))=TRUE, INDEX(S25_CF!T:T, MATCH("*" & $A14 & "*", CompanyList!A:A, 0))=TRUE, INDEX(S24_CF!W:W, MATCH("*" & $A14 & "*", CompanyList!A:A, 0))=TRUE), "Yes", "No")} -> Yes | S14: =IF(COUNTIF(S26_CF!$A:$A,"*" & $A14 & "*") <> 0, "Yes", "No") -> Yes | T14: {=INDEX(S26_CF!K:K, MATCH("*" & $A14 & "*", S26_CF!A:A, 0))} -> Basic One-Day: Wednesday, January 28th [$1000.00] | U14: =IF(COUNTIF(F25_CF!$A:$A,"*" & $A14 & "*") <> 0, "Yes", "No") -> No | V14: {=INDEX(F25_CF!I:I, MATCH("*" & $A14 & "*", F25_CF!$A:$A, 0))} -> #N/A | W14: =IF(COUNTIF(S25_CF!$A:$A,"*" & $A14 & "*") <> 0, "Yes", "No") -> Yes | X14: {=INDEX(S25_CF!J:J, MATCH("*" & $A14 & "*", S25_CF!$A:$A, 0))} -> Silver One-Day: Thursday, January 23rd [$1800.00] | Y14: =IF(COUNTIF(F24_CF!$A:$A,"*" & $A14 & "*") <> 0, "Yes", "No") -> Yes | Z14: {=INDEX(F24_CF!N:N, MATCH("*" & $A14 & "*", F24_CF!$A:$A, 0))} -> Gold One-Day: Thursday, September 5th [$2500.00] | AA14: =IF(COUNTIF(S24_CF!$A:$A,"*" & $A14 & "*") <> 0, "Yes", "No") -> Yes | AB14: {=INDEX(S24_CF!H:H, MATCH("*" & $A14 & "*", S24_CF!$A:$A, 0))} -> Basic Two-Day [$2000.00]
A15: Arion Blue, LLC | B15: Private | F15: =COUNTIF(S26_Emp!$C:$C,"*" &A15 & "*") -> 0 | G15: =COUNTIF(F25_Emp!$C:$C,"*" &#REF! & "*") -> 0 | H15: =COUNTIF(S25_Emp!$C:$C,"*" & A15 & "*") -> 0 | I15: =COUNTIF(F24_Emp!$C:$C,"*" & B15 & "*") -> 0 | J15: =COUNTIF(S24_Emp!$C:$C,"*" & $A15 & "*") -> 0 | K15: =COUNTIF(F23_Emp!$C:$C,"*" & $A15 & "*") -> 0 | L15: =COUNTIF(S23_Emp!$C:$C,"*" & $A15 & "*") -> 1 | M15: =COUNTIF(F22_Emp!$C:$C,"*" & $A15 & "*") -> 1 | N15: =COUNTIF(S22_Emp!$C:$C,"*" & $A15 & "*") -> 0 | O15: =COUNTIFS(S22_Emp!$C:$C,"*" & $A15 & "*", S22_S25_Emp!$B:$B, "Bachelor") -> #VALUE! | P15: =COUNTIFS(S22_Emp!$C:$C,"*" & $A15 & "*", S22_S25_Emp!$B:$B, "Master") -> #VALUE! | Q15: =COUNTIFS(S22_Emp!$C:$C,"*" & $A15 & "*", S22_S25_Emp!$B:$B, "Doctorate") -> #VALUE! | R15: {=IF(OR(INDEX(S26_CF!X:X, MATCH("*" & $A15 & "*", CompanyList!A:A, 0))=TRUE, INDEX(F25_CF!P:P, MATCH("*" & $A15 & "*", CompanyList!A:A, 0))=TRUE, INDEX(S25_CF!T:T, MATCH("*" & $A15 & "*", CompanyList!A:A, 0))=TRUE, INDEX(S24_CF!W:W, MATCH("*" & $A15 & "*", CompanyList!A:A, 0))=TRUE), "Yes", "No")} -> No | S15: =IF(COUNTIF(S26_CF!$A:$A,"*" & $A15 & "*") <> 0, "Yes", "No") -> Yes | T15: {=INDEX(S26_CF!K:K, MATCH("*" & $A15 & "*", S26_CF!A:A, 0))} -> Basic One-Day: Thursday, January 29th [$1000.00] | U15: =IF(COUNTIF(F25_CF!$A:$A,"*" & $A15 & "*") <> 0, "Yes", "No") -> Yes | V15: {=INDEX(F25_CF!I:I, MATCH("*" & $A15 & "*", F25_CF!$A:$A, 0))} -> Basic One-Day: Wednesday, September 10th [$1000.00] | W15: =IF(COUNTIF(S25_CF!$A:$A,"*" & $A15 & "*") <> 0, "Yes", "No") -> Yes | X15: {=INDEX(S25_CF!J:J, MATCH("*" & $A15 & "*", S25_CF!$A:$A, 0))} -> Basic One-Day: Wednesday, January 22nd [$1000.00] | Y15: =IF(COUNTIF(F24_CF!$A:$A,"*" & $A15 & "*") <> 0, "Yes", "No") -> No | Z15: {=INDEX(F24_CF!N:N, MATCH("*" & $A15 & "*", F24_CF!$A:$A, 0))} -> #N/A | AA15: =IF(COUNTIF(S24_CF!$A:$A,"*" & $A15 & "*") <> 0, "Yes", "No") -> Yes | AB15: {=INDEX(S24_CF!H:H, MATCH("*" & $A15 & "*", S24_CF!$A:$A, 0))} -> Basic One-Day [$1000.00]
A16: AtkinsRéalis | B16: Public | C16: 6500 | D16: 37000 | E16: 10 | F16: =COUNTIF(S26_Emp!$C:$C,"*" &A16 & "*") -> 0 | G16: =COUNTIF(F25_Emp!$C:$C,"*" &#REF! & "*") -> 0 | H16: =COUNTIF(S25_Emp!$C:$C,"*" & A16 & "*") -> 0 | I16: =COUNTIF(F24_Emp!$C:$C,"*" & B16 & "*") -> 1 | J16: =COUNTIF(S24_Emp!$C:$C,"*" & $A16 & "*") -> 2 | K16: =COUNTIF(F23_Emp!$C:$C,"*" & $A16 & "*") -> 1 | L16: =COUNTIF(S23_Emp!$C:$C,"*" & $A16 & "*") -> 0 | M16: =COUNTIF(F22_Emp!$C:$C,"*" & $A16 & "*") -> 0 | N16: =COUNTIF(S22_Emp!$C:$C,"*" & $A16 & "*") -> 0 | O16: =COUNTIFS(S22_Emp!$C:$C,"*" & $A16 & "*", S22_S25_Emp!$B:$B, "Bachelor") -> #VALUE! | P16: =COUNTIFS(S22_Emp!$C:$C,"*" & $A16 & "*", S22_S25_Emp!$B:$B, "Master") -> #VALUE! | Q16: =COUNTIFS(S22_Emp!$C:$C,"*" & $A16 & "*", S22_S25_Emp!$B:$B, "Doctorate") -> #VALUE! | R16: {=IF(OR(INDEX(S26_CF!X:X, MATCH("*" & $A16 & "*", CompanyList!A:A, 0))=TRUE, INDEX(F25_CF!P:P, MATCH("*" & $A16 & "*", CompanyList!A:A, 0))=TRUE, INDEX(S25_CF!T:T, MATCH("*" & $A16 & "*", CompanyList!A:A, 0))=TRUE, INDEX(S24_CF!W:W, MATCH("*" & $A16 & "*", CompanyList!A:A, 0))=TRUE), "Yes", "No")} -> Yes | S16: =IF(COUNTIF(S26_CF!$A:$A,"*" & $A16 & "*") <> 0, "Yes", "No") -> Yes | T16: {=INDEX(S26_CF!K:K, MATCH("*" & $A16 & "*", S26_CF!A:A, 0))} -> Basic One-Day: Wednesday, January 28th [$1000.00] | U16: =IF(COUNTIF(F25_CF!$A:$A,"*" & $A16 & "*") <> 0, "Yes", "No") -> Yes | V16: {=INDEX(F25_CF!I:I, MATCH("*" & $A16 & "*", F25_CF!$A:$A, 0))} -> Basic One-Day: Wednesday, September 10th [$1000.00] | W16: =IF(COUNTIF(S25_CF!$A:$A,"*" & $A16 & "*") <> 0, "Yes", "No") -> Yes | X16: {=INDEX(S25_CF!J:J, MATCH("*" & $A16 & "*", S25_CF!$A:$A, 0))} -> Basic One-Day: Wednesday, January 22nd [$1000.00] | Y16: =IF(COUNTIF(F24_CF!$A:$A,"*" & $A16 & "*") <> 0, "Yes", "No") -> Yes | Z16: {=INDEX(F24_CF!N:N, MATCH("*" & $A16 & "*", F24_CF!$A:$A, 0))} -> Basic One-Day: Wednesday, September 4th [$1000.00] | AA16: =IF(COUNTIF(S24_CF!$A:$A,"*" & $A16 & "*") <> 0, "Yes", "No") -> Yes | AB16: {=INDEX(S24_CF!H:H, MATCH("*" & $A16 & "*", S24_CF!$A:$A, 0))} -> Basic One-Day [$1000.00]
A17: Atlas Energy Solutions | B17: Private | F17: =COUNTIF(S26_Emp!$C:$C,"*" &A17 & "*") -> 0 | G17: =COUNTIF(F25_Emp!$C:$C,"*" &#REF! & "*") -> 0 | H17: =COUNTIF(S25_Emp!$C:$C,"*" & A17 & "*") -> 0 | I17: =COUNTIF(F24_Emp!$C:$C,"*" & B17 & "*") -> 0 | J17: =COUNTIF(S24_Emp!$C:$C,"*" & $A17 & "*") -> 0 | K17: =COUNTIF(F23_Emp!$C:$C,"*" & $A17 & "*") -> 0 | L17: =COUNTIF(S23_Emp!$C:$C,"*" & $A17 & "*") -> 0 | M17: =COUNTIF(F22_Emp!$C:$C,"*" & $A17 & "*") -> 0 | N17: =COUNTIF(S22_Emp!$C:$C,"*" & $A17 & "*") -> 0 | O17: =COUNTIFS(S22_Emp!$C:$C,"*" & $A17 & "*", S22_S25_Emp!$B:$B, "Bachelor") -> #VALUE! | P17: =COUNTIFS(S22_Emp!$C:$C,"*" & $A17 & "*", S22_S25_Emp!$B:$B, "Master") -> #VALUE! | Q17: =COUNTIFS(S22_Emp!$C:$C,"*" & $A17 & "*", S22_S25_Emp!$B:$B, "Doctorate") -> #VALUE! | R17: {=IF(OR(INDEX(S26_CF!X:X, MATCH("*" & $A17 & "*", CompanyList!A:A, 0))=TRUE, INDEX(F25_CF!P:P, MATCH("*" & $A17 & "*", CompanyList!A:A, 0))=TRUE, INDEX(S25_CF!T:T, MATCH("*" & $A17 & "*", CompanyList!A:A, 0))=TRUE, INDEX(S24_CF!W:W, MATCH("*" & $A17 & "*", CompanyList!A:A, 0))=TRUE), "Yes", "No")} -> No | S17: =IF(COUNTIF(S26_CF!$A:$A,"*" & $A17 & "*") <> 0, "Yes", "No") -> Yes | T17: {=INDEX(S26_CF!K:K, MATCH("*" & $A17 & "*", S26_CF!A:A, 0))} -> Basic One-Day: Thursday, January 29th [$1000.00] | U17: =IF(COUNTIF(F25_CF!$A:$A,"*" & $A17 & "*") <> 0, "Yes", "No") -> Yes | V17: {=INDEX(F25_CF!I:I, MATCH("*" & $A17 & "*", F25_CF!$A:$A, 0))} -> Basic One-Day: Thursday, September 11th [$1000.00] | W17: =IF(COUNTIF(S25_CF!$A:$A,"*" & $A17 & "*") <> 0, "Yes", "No") -> No | X17: {=INDEX(S25_CF!J:J, MATCH("*" & $A17 & "*", S25_CF!$A:$A, 0))} -> #N/A | Y17: =IF(COUNTIF(F24_CF!$A:$A,"*" & $A17 & "*") <> 0, "Yes", "No") -> Yes | Z17: {=INDEX(F24_CF!N:N, MATCH("*" & $A17 & "*", F24_CF!$A:$A, 0))} -> Basic One-Day: Wednesday, September 4th [$1000.00] | AA17: =IF(COUNTIF(S24_CF!$A:$A,"*" & $A17 & "*") <> 0, "Yes", "No") -> Yes | AB17: {=INDEX(S24_CF!H:H, MATCH("*" & $A17 & "*", S24_CF!$A:$A, 0))} -> Basic Two-Day [$2000.00]
A18: Atmos Energy | B18: Public | C18: 4200 | D18: 4800 | E18: 17 | F18: =COUNTIF(S26_Emp!$C:$C,"*" &A18 & "*") -> 0 | G18: =COUNTIF(F25_Emp!$C:$C,"*" &#REF! & "*") -> 0 | H18: =COUNTIF(S25_Emp!$C:$C,"*" & A18 & "*") -> 0 | I18: =COUNTIF(F24_Emp!$C:$C,"*" & B18 & "*") -> 1 | J18: =COUNTIF(S24_Emp!$C:$C,"*" & $A18 & "*") -> 2 | K18: =COUNTIF(F23_Emp!$C:$C,"*" & $A18 & "*") -> 0 | L18: =COUNTIF(S23_Emp!$C:$C,"*" & $A18 & "*") -> 0 | M18: =COUNTIF(F22_Emp!$C:$C,"*" & $A18 & "*") -> 0 | N18: =COUNTIF(S22_Emp!$C:$C,"*" & $A18 & "*") -> 0 | O18: =COUNTIFS(S22_Emp!$C:$C,"*" & $A18 & "*", S22_S25_Emp!$B:$B, "Bachelor") -> #VALUE! | P18: =COUNTIFS(S22_Emp!$C:$C,"*" & $A18 & "*", S22_S25_Emp!$B:$B, "Master") -> #VALUE! | Q18: =COUNTIFS(S22_Emp!$C:$C,"*" & $A18 & "*", S22_S25_Emp!$B:$B, "Doctorate") -> #VALUE! | R18: {=IF(OR(INDEX(S26_CF!X:X, MATCH("*" & $A18 & "*", CompanyList!A:A, 0))=TRUE, INDEX(F25_CF!P:P, MATCH("*" & $A18 & "*", CompanyList!A:A, 0))=TRUE, INDEX(S25_CF!T:T, MATCH("*" & $A18 & "*", CompanyList!A:A, 0))=TRUE, INDEX(S24_CF!W:W, MATCH("*" & $A18 & "*", CompanyList!A:A, 0))=TRUE), "Yes", "No")} -> Yes | S18: =IF(COUNTIF(S26_CF!$A:$A,"*" & $A18 & "*") <> 0, "Yes", "No") -> Yes | T18: {=INDEX(S26_CF!K:K, MATCH("*" & $A18 & "*", S26_CF!A:A, 0))} -> Basic One-Day: Wednesday, January 28th [$1000.00] | U18: =IF(COUNTIF(F25_CF!$A:$A,"*" & $A18 & "*") <> 0, "Yes", "No") -> Yes | V18: {=INDEX(F25_CF!I:I, MATCH("*" & $A18 & "*", F25_CF!$A:$A, 0))} -> Silver Two-Day [$3000.00] | W18: =IF(COUNTIF(S25_CF!$A:$A,"*" & $A18 & "*") <> 0, "Yes", "No") -> No | X18: {=INDEX(S25_CF!J:J, MATCH("*" & $A18 & "*", S25_CF!$A:$A, 0))} -> #N/A | Y18: =IF(COUNTIF(F24_CF!$A:$A,"*" & $A18 & "*") <> 0, "Yes", "No") -> Yes | Z18: {=INDEX(F24_CF!N:N, MATCH("*" & $A18 & "*", F24_CF!$A:$A, 0))} -> Silver Two-Day [$3000.00] | AA18: =IF(COUNTIF(S24_CF!$A:$A,"*" & $A18 & "*") <> 0, "Yes", "No") -> Yes | AB18: {=INDEX(S24_CF!H:H, MATCH("*" & $A18 & "*", S24_CF!$A:$A, 0))} -> Basic One-Day [$1000.00]
A19: Atwell, LLC | B19: Private | F19: =COUNTIF(S26_Emp!$C:$C,"*" &A19 & "*") -> 0 | G19: =COUNTIF(F25_Emp!$C:$C,"*" &#REF! & "*") -> 0 | H19: =COUNTIF(S25_Emp!$C:$C,"*" & A19 & "*") -> 0 | I19: =COUNTIF(F24_Emp!$C:$C,"*" & B19 & "*") -> 0 | J19: =COUNTIF(S24_Emp!$C:$C,"*" & $A19 & "*") -> 0 | K19: =COUNTIF(F23_Emp!$C:$C,"*" & $A19 & "*") -> 0 | L19: =COUNTIF(S23_Emp!$C:$C,"*" & $A19 & "*") -> 0 | M19: =COUNTIF(F22_Emp!$C:$C,"*" & $A19 & "*") -> 0 | N19: =COUNTIF(S22_Emp!$C:$C,"*" & $A19 & "*") -> 0 | O19: =COUNTIFS(S22_Emp!$C:$C,"*" & $A19 & "*", S22_S25_Emp!$B:$B, "Bachelor") -> #VALUE! | P19: =COUNTIFS(S22_Emp!$C:$C,"*" & $A19 & "*", S22_S25_Emp!$B:$B, "Master") -> #VALUE! | Q19: =COUNTIFS(S22_Emp!$C:$C,"*" & $A19 & "*", S22_S25_Emp!$B:$B, "Doctorate") -> #VALUE! | R19: {=IF(OR(INDEX(S26_CF!X:X, MATCH("*" & $A19 & "*", CompanyList!A:A, 0))=TRUE, INDEX(F25_CF!P:P, MATCH("*" & $A19 & "*", CompanyList!A:A, 0))=TRUE, INDEX(S25_CF!T:T, MATCH("*" & $A19 & "*", CompanyList!A:A, 0))=TRUE, INDEX(S24_CF!W:W, MATCH("*" & $A19 & "*", CompanyList!A:A, 0))=TRUE), "Yes", "No")} -> Yes | S19: =IF(COUNTIF(S26_CF!$A:$A,"*" & $A19 & "*") <> 0, "Yes", "No") -> Yes | T19: {=INDEX(S26_CF!K:K, MATCH("*" & $A19 & "*", S26_CF!A:A, 0))} -> Basic One-Day: Thursday, January 29th [$1000.00] | U19: =IF(COUNTIF(F25_CF!$A:$A,"*" & $A19 & "*") <> 0, "Yes", "No") -> Yes | V19: {=INDEX(F25_CF!I:I, MATCH("*" & $A19 & "*", F25_CF!$A:$A, 0))} -> Silver One-Day: Wednesday, September 10th [$1800.00] | W19: =IF(COUNTIF(S25_CF!$A:$A,"*" & $A19 & "*") <> 0, "Yes", "No") -> No | X19: {=INDEX(S25_CF!J:J, MATCH("*" & $A19 & "*", S25_CF!$A:$A, 0))} -> #N/A | Y19: =IF(COUNTIF(F24_CF!$A:$A,"*" & $A19 & "*") <> 0, "Yes", "No") -> Yes | Z19: {=INDEX(F24_CF!N:N, MATCH("*" & $A19 & "*", F24_CF!$A:$A, 0))} -> Basic One-Day: Wednesday, September 4th [$1000.00] | AA19: =IF(COUNTIF(S24_CF!$A:$A,"*" & $A19 & "*") <> 0, "Yes", "No") -> Yes | AB19: {=INDEX(S24_CF!H:H, MATCH("*" & $A19 & "*", S24_CF!$A:$A, 0))} -> Basic One-Day [$1000.00]
A20: Audubon Companies | B20: Private | F20: =COUNTIF(S26_Emp!$C:$C,"*" &A20 & "*") -> 0 | G20: =COUNTIF(F25_Emp!$C:$C,"*" &#REF! & "*") -> 0 | H20: =COUNTIF(S25_Emp!$C:$C,"*" & A20 & "*") -> 0 | I20: =COUNTIF(F24_Emp!$C:$C,"*" & B20 & "*") -> 0 | J20: =COUNTIF(S24_Emp!$C:$C,"*" & $A20 & "*") -> 0 | K20: =COUNTIF(F23_Emp!$C:$C,"*" & $A20 & "*") -> 0 | L20: =COUNTIF(S23_Emp!$C:$C,"*" & $A20 & "*") -> 1 | M20: =COUNTIF(F22_Emp!$C:$C,"*" & $A20 & "*") -> 0 | N20: =COUNTIF(S22_Emp!$C:$C,"*" & $A20 & "*") -> 0 | O20: =COUNTIFS(S22_Emp!$C:$C,"*" & $A20 & "*", S22_S25_Emp!$B:$B, "Bachelor") -> #VALUE! | P20: =COUNTIFS(S22_Emp!$C:$C,"*" & $A20 & "*", S22_S25_Emp!$B:$B, "Master") -> #VALUE! | Q20: =COUNTIFS(S22_Emp!$C:$C,"*" & $A20 & "*", S22_S25_Emp!$B:$B, "Doctorate") -> #VALUE! | R20: {=IF(OR(INDEX(S26_CF!X:X, MATCH("*" & $A20 & "*", CompanyList!A:A, 0))=TRUE, INDEX(F25_CF!P:P, MATCH("*" & $A20 & "*", CompanyList!A:A, 0))=TRUE, INDEX(S25_CF!T:T, MATCH("*" & $A20 & "*", CompanyList!A:A, 0))=TRUE, INDEX(S24_CF!W:W, MATCH("*" & $A20 & "*", CompanyList!A:A, 0))=TRUE), "Yes", "No")} -> Yes | S20: =IF(COUNTIF(S26_CF!$A:$A,"*" & $A20 & "*") <> 0, "Yes", "No") -> Yes | T20: {=INDEX(S26_CF!K:K, MATCH("*" & $A20 & "*", S26_CF!A:A, 0))} -> Basic One-Day: Wednesday, January 28th [$1000.00] | U20: =IF(COUNTIF(F25_CF!$A:$A,"*" & $A20 & "*") <> 0, "Yes", "No") -> Yes | V20: {=INDEX(F25_CF!I:I, MATCH("*" & $A20 & "*", F25_CF!$A:$A, 0))} -> Basic One-Day: Wednesday, September 10th [$1000.00] | W20: =IF(COUNTIF(S25_CF!$A:$A,"*" & $A20 & "*") <> 0, "Yes", "No") -> Yes | X20: {=INDEX(S25_CF!J:J, MATCH("*" & $A20 & "*", S25_CF!$A:$A, 0))} -> Basic One-Day: Thursday, January 23rd [$1000.00] | Y20: =IF(COUNTIF(F24_CF!$A:$A,"*" & $A20 & "*") <> 0, "Yes", "No") -> Yes | Z20: {=INDEX(F24_CF!N:N, MATCH("*" & $A20 & "*", F24_CF!$A:$A, 0))} -> Basic One-Day: Wednesday, September 4th [$1000.00] | AA20: =IF(COUNTIF(S24_CF!$A:$A,"*" & $A20 & "*") <> 0, "Yes", "No") -> Yes | AB20: {=INDEX(S24_CF!H:H, MATCH("*" & $A20 & "*", S24_CF!$A:$A, 0))} -> Basic One-Day [$1000.00]
A21: Austin Bridge & Road, L.P. | B21: Private | F21: =COUNTIF(S26_Emp!$C:$C,"*" &A21 & "*") -> 0 | G21: =COUNTIF(F25_Emp!$C:$C,"*" &#REF! & "*") -> 0 | H21: =COUNTIF(S25_Emp!$C:$C,"*" & A21 & "*") -> 0 | I21: =COUNTIF(F24_Emp!$C:$C,"*" & B21 & "*") -> 0 | J21: =COUNTIF(S24_Emp!$C:$C,"*" & $A21 & "*") -> 0 | K21: =COUNTIF(F23_Emp!$C:$C,"*" & $A21 & "*") -> 1 | L21: =COUNTIF(S23_Emp!$C:$C,"*" & $A21 & "*") -> 0 | M21: =COUNTIF(F22_Emp!$C:$C,"*" & $A21 & "*") -> 0 | N21: =COUNTIF(S22_Emp!$C:$C,"*" & $A21 & "*") -> 0 | O21: =COUNTIFS(S22_Emp!$C:$C,"*" & $A21 & "*", S22_S25_Emp!$B:$B, "Bachelor") -> #VALUE! | P21: =COUNTIFS(S22_Emp!$C:$C,"*" & $A21 & "*", S22_S25_Emp!$B:$B, "Master") -> #VALUE! | Q21: =COUNTIFS(S22_Emp!$C:$C,"*" & $A21 & "*", S22_S25_Emp!$B:$B, "Doctorate") -> #VALUE! | R21: {=IF(OR(INDEX(S26_CF!X:X, MATCH("*" & $A21 & "*", CompanyList!A:A, 0))=TRUE, INDEX(F25_CF!P:P, MATCH("*" & $A21 & "*", CompanyList!A:A, 0))=TRUE, INDEX(S25_CF!T:T, MATCH("*" & $A21 & "*", CompanyList!A:A, 0))=TRUE, INDEX(S24_CF!W:W, MATCH("*" & $A21 & "*", CompanyList!A:A, 0))=TRUE), "Yes", "No")} -> Yes | S21: =IF(COUNTIF(S26_CF!$A:$A,"*" & $A21 & "*") <> 0, "Yes", "No") -> Yes | T21: {=INDEX(S26_CF!K:K, MATCH("*" & $A21 & "*", S26_CF!A:A, 0))} -> Basic One-Day: Wednesday, January 28th [$1000.00] | U21: =IF(COUNTIF(F25_CF!$A:$A,"*" & $A21 & "*") <> 0, "Yes", "No") -> Yes | V21: {=INDEX(F25_CF!I:I, MATCH("*" & $A21 & "*", F25_CF!$A:$A, 0))} -> Basic One-Day: Thursday, September 11th [$1000.00] | W21: =IF(COUNTIF(S25_CF!$A:$A,"*" & $A21 & "*") <> 0, "Yes", "No") -> Yes | X21: {=INDEX(S25_CF!J:J, MATCH("*" & $A21 & "*", S25_CF!$A:$A, 0))} -> Basic One-Day: Wednesday, January 22nd [$1000.00] | Y21: =IF(COUNTIF(F24_CF!$A:$A,"*" & $A21 & "*") <> 0, "Yes", "No") -> Yes | Z21: {=INDEX(F24_CF!N:N, MATCH("*" & $A21 & "*", F24_CF!$A:$A, 0))} -> Silver One-Day: Thursday, September 5th [$1800.00] | AA21: =IF(COUNTIF(S24_CF!$A:$A,"*" & $A21 & "*") <> 0, "Yes", "No") -> Yes | AB21: {=INDEX(S24_CF!H:H, MATCH("*" & $A21 & "*", S24_CF!$A:$A, 0))} -> Silver One-Day [$1800.00]
A22: Baird, Hampton & Brown | B22: Private | F22: =COUNTIF(S26_Emp!$C:$C,"*" &A22 & "*") -> 0 | G22: =COUNTIF(F25_Emp!$C:$C,"*" &#REF! & "*") -> 0 | H22: =COUNTIF(S25_Emp!$C:$C,"*" & A22 & "*") -> 0 | I22: =COUNTIF(F24_Emp!$C:$C,"*" & B22 & "*") -> 0 | J22: =COUNTIF(S24_Emp!$C:$C,"*" & $A22 & "*") -> 3 | K22: =COUNTIF(F23_Emp!$C:$C,"*" & $A22 & "*") -> 0 | L22: =COUNTIF(S23_Emp!$C:$C,"*" & $A22 & "*") -> 0 | M22: =COUNTIF(F22_Emp!$C:$C,"*" & $A22 & "*") -> 1 | N22: =COUNTIF(S22_Emp!$C:$C,"*" & $A22 & "*") -> 0 | O22: =COUNTIFS(S22_Emp!$C:$C,"*" & $A22 & "*", S22_S25_Emp!$B:$B, "Bachelor") -> #VALUE! | P22: =COUNTIFS(S22_Emp!$C:$C,"*" & $A22 & "*", S22_S25_Emp!$B:$B, "Master") -> #VALUE! | Q22: =COUNTIFS(S22_Emp!$C:$C,"*" & $A22 & "*", S22_S25_Emp!$B:$B, "Doctorate") -> #VALUE! | R22: {=IF(OR(INDEX(S26_CF!X:X, MATCH("*" & $A22 & "*", CompanyList!A:A, 0))=TRUE, INDEX(F25_CF!P:P, MATCH("*" & $A22 & "*", CompanyList!A:A, 0))=TRUE, INDEX(S25_CF!T:T, MATCH("*" & $A22 & "*", CompanyList!A:A, 0))=TRUE, INDEX(S24_CF!W:W, MATCH("*" & $A22 & "*", CompanyList!A:A, 0))=TRUE), "Yes", "No")} -> Yes | S22: =IF(COUNTIF(S26_CF!$A:$A,"*" & $A22 & "*") <> 0, "Yes", "No") -> Yes | T22: {=INDEX(S26_CF!K:K, MATCH("*" & $A22 & "*", S26_CF!A:A, 0))} -> Basic One-Day: Wednesday, January 28th [$1000.00] | U22: =IF(COUNTIF(F25_CF!$A:$A,"*" & $A22 & "*") <> 0, "Yes", "No") -> Yes | V22: {=INDEX(F25_CF!I:I, MATCH("*" & $A22 & "*", F25_CF!$A:$A, 0))} -> Basic One-Day: Wednesday, September 10th [$1000.00] | W22: =IF(COUNTIF(S25_CF!$A:$A,"*" & $A22 & "*") <> 0, "Yes", "No") -> Yes | X22: {=INDEX(S25_CF!J:J, MATCH("*" & $A22 & "*", S25_CF!$A:$A, 0))} -> Basic One-Day: Thursday, January 23rd [$1000.00] | Y22: =IF(COUNTIF(F24_CF!$A:$A,"*" & $A22 & "*") <> 0, "Yes", "No") -> Yes | Z22: {=INDEX(F24_CF!N:N, MATCH("*" & $A22 & "*", F24_CF!$A:$A, 0))} -> Basic One-Day: Thursday, September 5th [$1000.00] | AA22: =IF(COUNTIF(S24_CF!$A:$A,"*" & $A22 & "*") <> 0, "Yes", "No") -> Yes | AB22: {=INDEX(S24_CF!H:H, MATCH("*" & $A22 & "*", S24_CF!$A:$A, 0))} -> Basic One-Day [$1000.00]
A23: Baker Concrete Construction | B23: Private | F23: =COUNTIF(S26_Emp!$C:$C,"*" &A23 & "*") -> 0 | G23: =COUNTIF(F25_Emp!$C:$C,"*" &#REF! & "*") -> 0 | H23: =COUNTIF(S25_Emp!$C:$C,"*" & A23 & "*") -> 0 | I23: =COUNTIF(F24_Emp!$C:$C,"*" & B23 & "*") -> 0 | J23: =COUNTIF(S24_Emp!$C:$C,"*" & $A23 & "*") -> 0 | K23: =COUNTIF(F23_Emp!$C:$C,"*" & $A23 & "*") -> 0 | L23: =COUNTIF(S23_Emp!$C:$C,"*" & $A23 & "*") -> 0 | M23: =COUNTIF(F22_Emp!$C:$C,"*" & $A23 & "*") -> 1 | N23: =COUNTIF(S22_Emp!$C:$C,"*" & $A23 & "*") -> 0 | O23: =COUNTIFS(S22_Emp!$C:$C,"*" & $A23 & "*", S22_S25_Emp!$B:$B, "Bachelor") -> #VALUE! | P23: =COUNTIFS(S22_Emp!$C:$C,"*" & $A23 & "*", S22_S25_Emp!$B:$B, "Master") -> #VALUE! | Q23: =COUNTIFS(S22_Emp!$C:$C,"*" & $A23 & "*", S22_S25_Emp!$B:$B, "Doctorate") -> #VALUE! | R23: {=IF(OR(INDEX(S26_CF!X:X, MATCH("*" & $A23 & "*", CompanyList!A:A, 0))=TRUE, INDEX(F25_CF!P:P, MATCH("*" & $A23 & "*", CompanyList!A:A, 0))=TRUE, INDEX(S25_CF!T:T, MATCH("*" & $A23 & "*", CompanyList!A:A, 0))=TRUE, INDEX(S24_CF!W:W, MATCH("*" & $A23 & "*", CompanyList!A:A, 0))=TRUE), "Yes", "No")} -> Yes | S23: =IF(COUNTIF(S26_CF!$A:$A,"*" & $A23 & "*") <> 0, "Yes", "No") -> Yes | T23: {=INDEX(S26_CF!K:K, MATCH("*" & $A23 & "*", S26_CF!A:A, 0))} -> Basic One-Day: Wednesday, January 28th [$1000.00] | U23: =IF(COUNTIF(F25_CF!$A:$A,"*" & $A23 & "*") <> 0, "Yes", "No") -> No | V23: {=INDEX(F25_CF!I:I, MATCH("*" & $A23 & "*", F25_CF!$A:$A, 0))} -> #N/A | W23: =IF(COUNTIF(S25_CF!$A:$A,"*" & $A23 & "*") <> 0, "Yes", "No") -> No | X23: {=INDEX(S25_CF!J:J, MATCH("*" & $A23 & "*", S25_CF!$A:$A, 0))} -> #N/A | Y23: =IF(COUNTIF(F24_CF!$A:$A,"*" & $A23 & "*") <> 0, "Yes", "No") -> Yes | Z23: {=INDEX(F24_CF!N:N, MATCH("*" & $A23 & "*", F24_CF!$A:$A, 0))} -> Basic Two-Day [$2000.00] | AA23: =IF(COUNTIF(S24_CF!$A:$A,"*" & $A23 & "*") <> 0, "Yes", "No") -> Yes | AB23: {=INDEX(S24_CF!H:H, MATCH("*" & $A23 & "*", S24_CF!$A:$A, 0))} -> Basic Two-Day [$2000.00]
A24: Baker Hughes | B24: Public | C24: 25500 | D24: 58000 | E24: 35 | F24: =COUNTIF(S26_Emp!$C:$C,"*" &A24 & "*") -> 0 | G24: =COUNTIF(F25_Emp!$C:$C,"*" &#REF! & "*") -> 0 | H24: =COUNTIF(S25_Emp!$C:$C,"*" & A24 & "*") -> 2 | I24: =COUNTIF(F24_Emp!$C:$C,"*" & B24 & "*") -> 1 | J24: =COUNTIF(S24_Emp!$C:$C,"*" & $A24 & "*") -> 2 | K24: =COUNTIF(F23_Emp!$C:$C,"*" & $A24 & "*") -> 0 | L24: =COUNTIF(S23_Emp!$C:$C,"*" & $A24 & "*") -> 1 | M24: =COUNTIF(F22_Emp!$C:$C,"*" & $A24 & "*") -> 0 | N24: =COUNTIF(S22_Emp!$C:$C,"*" & $A24 & "*") -> 6 | O24: =COUNTIFS(S22_Emp!$C:$C,"*" & $A24 & "*", S22_S25_Emp!$B:$B, "Bachelor") -> #VALUE! | P24: =COUNTIFS(S22_Emp!$C:$C,"*" & $A24 & "*", S22_S25_Emp!$B:$B, "Master") -> #VALUE! | Q24: =COUNTIFS(S22_Emp!$C:$C,"*" & $A24 & "*", S22_S25_Emp!$B:$B, "Doctorate") -> #VALUE! | R24: {=IF(OR(INDEX(S26_CF!X:X, MATCH("*" & $A24 & "*", CompanyList!A:A, 0))=TRUE, INDEX(F25_CF!P:P, MATCH("*" & $A24 & "*", CompanyList!A:A, 0))=TRUE, INDEX(S25_CF!T:T, MATCH("*" & $A24 & "*", CompanyList!A:A, 0))=TRUE, INDEX(S24_CF!W:W, MATCH("*" & $A24 & "*", CompanyList!A:A, 0))=TRUE), "Yes", "No")} -> Yes | S24: =IF(COUNTIF(S26_CF!$A:$A,"*" & $A24 & "*") <> 0, "Yes", "No") -> Yes | T24: {=INDEX(S26_CF!K:K, MATCH("*" & $A24 & "*", S26_CF!A:A, 0))} -> Gold One-Day: Wednesday, January 28th [$2500.00] | U24: =IF(COUNTIF(F25_CF!$A:$A,"*" & $A24 & "*") <> 0, "Yes", "No") -> Yes | V24: {=INDEX(F25_CF!I:I, MATCH("*" & $A24 & "*", F25_CF!$A:$A, 0))} -> Gold One-Day: Wednesday, September 10th [$2500.00] | W24: =IF(COUNTIF(S25_CF!$A:$A,"*" & $A24 & "*") <> 0, "Yes", "No") -> Yes | X24: {=INDEX(S25_CF!J:J, MATCH("*" & $A24 & "*", S25_CF!$A:$A, 0))} -> Gold Two-Day [$5500.00] | Y24: =IF(COUNTIF(F24_CF!$A:$A,"*" & $A24 & "*") <> 0, "Yes", "No") -> Yes | Z24: {=INDEX(F24_CF!N:N, MATCH("*" & $A24 & "*", F24_CF!$A:$A, 0))} -> Silver Two-Day [$3000.00] | AA24: =IF(COUNTIF(S24_CF!$A:$A,"*" & $A24 & "*") <> 0, "Yes", "No") -> Yes | AB24: {=INDEX(S24_CF!H:H, MATCH("*" & $A24 & "*", S24_CF!$A:$A, 0))} -> Basic One-Day [$1000.00]
A25: Beckhoff Automation | B25: Private | F25: =COUNTIF(S26_Emp!$C:$C,"*" &A25 & "*") -> 0 | G25: =COUNTIF(F25_Emp!$C:$C,"*" &#REF! & "*") -> 0 | H25: =COUNTIF(S25_Emp!$C:$C,"*" & A25 & "*") -> 0 | I25: =COUNTIF(F24_Emp!$C:$C,"*" & B25 & "*") -> 0 | J25: =COUNTIF(S24_Emp!$C:$C,"*" & $A25 & "*") -> 0 | K25: =COUNTIF(F23_Emp!$C:$C,"*" & $A25 & "*") -> 0 | L25: =COUNTIF(S23_Emp!$C:$C,"*" & $A25 & "*") -> 2 | M25: =COUNTIF(F22_Emp!$C:$C,"*" & $A25 & "*") -> 1 | N25: =COUNTIF(S22_Emp!$C:$C,"*" & $A25 & "*") -> 1 | O25: =COUNTIFS(S22_Emp!$C:$C,"*" & $A25 & "*", S22_S25_Emp!$B:$B, "Bachelor") -> #VALUE! | P25: =COUNTIFS(S22_Emp!$C:$C,"*" & $A25 & "*", S22_S25_Emp!$B:$B, "Master") -> #VALUE! | Q25: =COUNTIFS(S22_Emp!$C:$C,"*" & $A25 & "*", S22_S25_Emp!$B:$B, "Doctorate") -> #VALUE! | R25: {=IF(OR(INDEX(S26_CF!X:X, MATCH("*" & $A25 & "*", CompanyList!A:A, 0))=TRUE, INDEX(F25_CF!P:P, MATCH("*" & $A25 & "*", CompanyList!A:A, 0))=TRUE, INDEX(S25_CF!T:T, MATCH("*" & $A25 & "*", CompanyList!A:A, 0))=TRUE, INDEX(S24_CF!W:W, MATCH("*" & $A25 & "*", CompanyList!A:A, 0))=TRUE), "Yes", "No")} -> Yes | S25: =IF(COUNTIF(S26_CF!$A:$A,"*" & $A25 & "*") <> 0, "Yes", "No") -> No | T25: {=INDEX(S26_CF!K:K, MATCH("*" & $A25 & "*", S26_CF!A:A, 0))} -> #N/A | U25: =IF(COUNTIF(F25_CF!$A:$A,"*" & $A25 & "*") <> 0, "Yes", "No") -> Yes | V25: {=INDEX(F25_CF!I:I, MATCH("*" & $A25 & "*", F25_CF!$A:$A, 0))} -> Silver Two-Day [$3000.00] | W25: =IF(COUNTIF(S25_CF!$A:$A,"*" & $A25 & "*") <> 0, "Yes", "No") -> No | X25: {=INDEX(S25_CF!J:J, MATCH("*" & $A25 & "*", S25_CF!$A:$A, 0))} -> #N/A | Y25: =IF(COUNTIF(F24_CF!$A:$A,"*" & $A25 & "*") <> 0, "Yes", "No") -> Yes | Z25: {=INDEX(F24_CF!N:N, MATCH("*" & $A25 & "*", F24_CF!$A:$A, 0))} -> Silver Two-Day [$3000.00] | AA25: =IF(COUNTIF(S24_CF!$A:$A,"*" & $A25 & "*") <> 0, "Yes", "No") -> Yes | AB25: {=INDEX(S24_CF!H:H, MATCH("*" & $A25 & "*", S24_CF!$A:$A, 0))} -> Silver Two-Day [$3000.00]
A26: Bernhard | B26: Private | F26: =COUNTIF(S26_Emp!$C:$C,"*" &A26 & "*") -> 0 | G26: =COUNTIF(F25_Emp!$C:$C,"*" &#REF! & "*") -> 0 | H26: =COUNTIF(S25_Emp!$C:$C,"*" & A26 & "*") -> 0 | I26: =COUNTIF(F24_Emp!$C:$C,"*" & B26 & "*") -> 0 | J26: =COUNTIF(S24_Emp!$C:$C,"*" & $A26 & "*") -> 0 | K26: =COUNTIF(F23_Emp!$C:$C,"*" & $A26 & "*") -> 0 | L26: =COUNTIF(S23_Emp!$C:$C,"*" & $A26 & "*") -> 0 | M26: =COUNTIF(F22_Emp!$C:$C,"*" & $A26 & "*") -> 0 | N26: =COUNTIF(S22_Emp!$C:$C,"*" & $A26 & "*") -> 0 | O26: =COUNTIFS(S22_Emp!$C:$C,"*" & $A26 & "*", S22_S25_Emp!$B:$B, "Bachelor") -> #VALUE! | P26: =COUNTIFS(S22_Emp!$C:$C,"*" & $A26 & "*", S22_S25_Emp!$B:$B, "Master") -> #VALUE! | Q26: =COUNTIFS(S22_Emp!$C:$C,"*" & $A26 & "*", S22_S25_Emp!$B:$B, "Doctorate") -> #VALUE! | R26: {=IF(OR(INDEX(S26_CF!X:X, MATCH("*" & $A26 & "*", CompanyList!A:A, 0))=TRUE, INDEX(F25_CF!P:P, MATCH("*" & $A26 & "*", CompanyList!A:A, 0))=TRUE, INDEX(S25_CF!T:T, MATCH("*" & $A26 & "*", CompanyList!A:A, 0))=TRUE, INDEX(S24_CF!W:W, MATCH("*" & $A26 & "*", CompanyList!A:A, 0))=TRUE), "Yes", "No")} -> No | S26: =IF(COUNTIF(S26_CF!$A:$A,"*" & $A26 & "*") <> 0, "Yes", "No") -> No | T26: {=INDEX(S26_CF!K:K, MATCH("*" & $A26 & "*", S26_CF!A:A, 0))} -> #N/A | U26: =IF(COUNTIF(F25_CF!$A:$A,"*" & $A26 & "*") <> 0, "Yes", "No") -> Yes | V26: {=INDEX(F25_CF!I:I, MATCH("*" & $A26 & "*", F25_CF!$A:$A, 0))} -> Basic One-Day: Thursday, September 11th [$1000.00] | W26: =IF(COUNTIF(S25_CF!$A:$A,"*" & $A26 & "*") <> 0, "Yes", "No") -> No | X26: {=INDEX(S25_CF!J:J, MATCH("*" & $A26 & "*", S25_CF!$A:$A, 0))} -> #N/A | Y26: =IF(COUNTIF(F24_CF!$A:$A,"*" & $A26 & "*") <> 0, "Yes", "No") -> Yes | Z26: {=INDEX(F24_CF!N:N, MATCH("*" & $A26 & "*", F24_CF!$A:$A, 0))} -> Basic One-Day: Wednesday, September 4th [$1000.00] | AA26: =IF(COUNTIF(S24_CF!$A:$A,"*" & $A26 & "*") <> 0, "Yes", "No") -> Yes | AB26: {=INDEX(S24_CF!H:H, MATCH("*" & $A26 & "*", S24_CF!$A:$A, 0))} -> Basic One-Day [$1000.00]
A27: BGE, Inc | B27: Private | F27: =COUNTIF(S26_Emp!$C:$C,"*" &A27 & "*") -> 0 | G27: =COUNTIF(F25_Emp!$C:$C,"*" &#REF! & "*") -> 0 | H27: =COUNTIF(S25_Emp!$C:$C,"*" & A27 & "*") -> 0 | I27: =COUNTIF(F24_Emp!$C:$C,"*" & B27 & "*") -> 0 | J27: =COUNTIF(S24_Emp!$C:$C,"*" & $A27 & "*") -> 3 | K27: =COUNTIF(F23_Emp!$C:$C,"*" & $A27 & "*") -> 1 | L27: =COUNTIF(S23_Emp!$C:$C,"*" & $A27 & "*") -> 1 | M27: =COUNTIF(F22_Emp!$C:$C,"*" & $A27 & "*") -> 2 | N27: =COUNTIF(S22_Emp!$C:$C,"*" & $A27 & "*") -> 0 | O27: =COUNTIFS(S22_Emp!$C:$C,"*" & $A27 & "*", S22_S25_Emp!$B:$B, "Bachelor") -> #VALUE! | P27: =COUNTIFS(S22_Emp!$C:$C,"*" & $A27 & "*", S22_S25_Emp!$B:$B, "Master") -> #VALUE! | Q27: =COUNTIFS(S22_Emp!$C:$C,"*" & $A27 & "*", S22_S25_Emp!$B:$B, "Doctorate") -> #VALUE! | R27: {=IF(OR(INDEX(S26_CF!X:X, MATCH("*" & $A27 & "*", CompanyList!A:A, 0))=TRUE, INDEX(F25_CF!P:P, MATCH("*" & $A27 & "*", CompanyList!A:A, 0))=TRUE, INDEX(S25_CF!T:T, MATCH("*" & $A27 & "*", CompanyList!A:A, 0))=TRUE, INDEX(S24_CF!W:W, MATCH("*" & $A27 & "*", CompanyList!A:A, 0))=TRUE), "Yes", "No")} -> Yes | S27: =IF(COUNTIF(S26_CF!$A:$A,"*" & $A27 & "*") <> 0, "Yes", "No") -> Yes | T27: {=INDEX(S26_CF!K:K, MATCH("*" & $A27 & "*", S26_CF!A:A, 0))} -> Gold Two-Day [$5500.00] | U27: =IF(COUNTIF(F25_CF!$A:$A,"*" & $A27 & "*") <> 0, "Yes", "No") -> Yes | V27: {=INDEX(F25_CF!I:I, MATCH("*" & $A27 & "*", F25_CF!$A:$A, 0))} -> Gold Two-Day [$5500.00] | W27: =IF(COUNTIF(S25_CF!$A:$A,"*" & $A27 & "*") <> 0, "Yes", "No") -> Yes | X27: {=INDEX(S25_CF!J:J, MATCH("*" & $A27 & "*", S25_CF!$A:$A, 0))} -> Gold Two-Day [$5500.00] | Y27: =IF(COUNTIF(F24_CF!$A:$A,"*" & $A27 & "*") <> 0, "Yes", "No") -> Yes | Z27: {=INDEX(F24_CF!N:N, MATCH("*" & $A27 & "*", F24_CF!$A:$A, 0))} -> Gold Two-Day [$5500.00] | AA27: =IF(COUNTIF(S24_CF!$A:$A,"*" & $A27 & "*") <> 0, "Yes", "No") -> Yes | AB27: {=INDEX(S24_CF!H:H, MATCH("*" & $A27 & "*", S24_CF!$A:$A, 0))} -> Gold Two-Day [$5000.00]
A28: Black & Veatch | B28: Private | C28: 4200 | D28: 12000 | F28: =COUNTIF(S26_Emp!$C:$C,"*" &A28 & "*") -> 0 | G28: =COUNTIF(F25_Emp!$C:$C,"*" &#REF! & "*") -> 0 | H28: =COUNTIF(S25_Emp!$C:$C,"*" & A28 & "*") -> 3 | I28: =COUNTIF(F24_Emp!$C:$C,"*" & B28 & "*") -> 0 | J28: =COUNTIF(S24_Emp!$C:$C,"*" & $A28 & "*") -> 1 | K28: =COUNTIF(F23_Emp!$C:$C,"*" & $A28 & "*") -> 1 | L28: =COUNTIF(S23_Emp!$C:$C,"*" & $A28 & "*") -> 0 | M28: =COUNTIF(F22_Emp!$C:$C,"*" & $A28 & "*") -> 2 | N28: =COUNTIF(S22_Emp!$C:$C,"*" & $A28 & "*") -> 2 | O28: =COUNTIFS(S22_Emp!$C:$C,"*" & $A28 & "*", S22_S25_Emp!$B:$B, "Bachelor") -> #VALUE! | P28: =COUNTIFS(S22_Emp!$C:$C,"*" & $A28 & "*", S22_S25_Emp!$B:$B, "Master") -> #VALUE! | Q28: =COUNTIFS(S22_Emp!$C:$C,"*" & $A28 & "*", S22_S25_Emp!$B:$B, "Doctorate") -> #VALUE! | R28: {=IF(OR(INDEX(S26_CF!X:X, MATCH("*" & $A28 & "*", CompanyList!A:A, 0))=TRUE, INDEX(F25_CF!P:P, MATCH("*" & $A28 & "*", CompanyList!A:A, 0))=TRUE, INDEX(S25_CF!T:T, MATCH("*" & $A28 & "*", CompanyList!A:A, 0))=TRUE, INDEX(S24_CF!W:W, MATCH("*" & $A28 & "*", CompanyList!A:A, 0))=TRUE), "Yes", "No")} -> No | S28: =IF(COUNTIF(S26_CF!$A:$A,"*" & $A28 & "*") <> 0, "Yes", "No") -> Yes | T28: {=INDEX(S26_CF!K:K, MATCH("*" & $A28 & "*", S26_CF!A:A, 0))} -> Basic One-Day: Wednesday, January 28th [$1000.00] | U28: =IF(COUNTIF(F25_CF!$A:$A,"*" & $A28 & "*") <> 0, "Yes", "No") -> Yes | V28: {=INDEX(F25_CF!I:I, MATCH("*" & $A28 & "*", F25_CF!$A:$A, 0))} -> Basic One-Day: Wednesday, September 10th [$1000.00] | W28: =IF(COUNTIF(S25_CF!$A:$A,"*" & $A28 & "*") <> 0, "Yes", "No") -> Yes | X28: {=INDEX(S25_CF!J:J, MATCH("*" & $A28 & "*", S25_CF!$A:$A, 0))} -> Basic One-Day: Thursday, January 23rd [$1000.00] | Y28: =IF(COUNTIF(F24_CF!$A:$A,"*" & $A28 & "*") <> 0, "Yes", "No") -> Yes | Z28: {=INDEX(F24_CF!N:N, MATCH("*" & $A28 & "*", F24_CF!$A:$A, 0))} -> Basic One-Day: Wednesday, September 4th [$1000.00] | AA28: =IF(COUNTIF(S24_CF!$A:$A,"*" & $A28 & "*") <> 0, "Yes", "No") -> Yes | AB28: {=INDEX(S24_CF!H:H, MATCH("*" & $A28 & "*", S24_CF!$A:$A, 0))} -> Basic One-Day [$1000.00]
A29: BNSF Railway | B29: Private (Sub of Berkshire) | C29: 23000 | D29: 36000 | F29: =COUNTIF(S26_Emp!$C:$C,"*" &A29 & "*") -> 0 | G29: =COUNTIF(F25_Emp!$C:$C,"*" &#REF! & "*") -> 0 | H29: =COUNTIF(S25_Emp!$C:$C,"*" & A29 & "*") -> 0 | I29: =COUNTIF(F24_Emp!$C:$C,"*" & B29 & "*") -> 0 | J29: =COUNTIF(S24_Emp!$C:$C,"*" & $A29 & "*") -> 1 | K29: =COUNTIF(F23_Emp!$C:$C,"*" & $A29 & "*") -> 0 | L29: =COUNTIF(S23_Emp!$C:$C,"*" & $A29 & "*") -> 4 | M29: =COUNTIF(F22_Emp!$C:$C,"*" & $A29 & "*") -> 0 | N29: =COUNTIF(S22_Emp!$C:$C,"*" & $A29 & "*") -> 2 | O29: =COUNTIFS(S22_Emp!$C:$C,"*" & $A29 & "*", S22_S25_Emp!$B:$B, "Bachelor") -> #VALUE! | P29: =COUNTIFS(S22_Emp!$C:$C,"*" & $A29 & "*", S22_S25_Emp!$B:$B, "Master") -> #VALUE! | Q29: =COUNTIFS(S22_Emp!$C:$C,"*" & $A29 & "*", S22_S25_Emp!$B:$B, "Doctorate") -> #VALUE! | R29: {=IF(OR(INDEX(S26_CF!X:X, MATCH("*" & $A29 & "*", CompanyList!A:A, 0))=TRUE, INDEX(F25_CF!P:P, MATCH("*" & $A29 & "*", CompanyList!A:A, 0))=TRUE, INDEX(S25_CF!T:T, MATCH("*" & $A29 & "*", CompanyList!A:A, 0))=TRUE, INDEX(S24_CF!W:W, MATCH("*" & $A29 & "*", CompanyList!A:A, 0))=TRUE), "Yes", "No")} -> No | S29: =IF(COUNTIF(S26_CF!$A:$A,"*" & $A29 & "*") <> 0, "Yes", "No") -> Yes | T29: {=INDEX(S26_CF!K:K, MATCH("*" & $A29 & "*", S26_CF!A:A, 0))} -> Basic Two-Day [$2000.00] | U29: =IF(COUNTIF(F25_CF!$A:$A,"*" & $A29 & "*") <> 0, "Yes", "No") -> Yes | V29: {=INDEX(F25_CF!I:I, MATCH("*" & $A29 & "*", F25_CF!$A:$A, 0))} -> Basic Two-Day [$2000.00] | W29: =IF(COUNTIF(S25_CF!$A:$A,"*" & $A29 & "*") <> 0, "Yes", "No") -> No | X29: {=INDEX(S25_CF!J:J, MATCH("*" & $A29 & "*", S25_CF!$A:$A, 0))} -> #N/A | Y29: =IF(COUNTIF(F24_CF!$A:$A,"*" & $A29 & "*") <> 0, "Yes", "No") -> Yes | Z29: {=INDEX(F24_CF!N:N, MATCH("*" & $A29 & "*", F24_CF!$A:$A, 0))} -> Basic One-Day: Wednesday, September 4th [$1000.00] | AA29: =IF(COUNTIF(S24_CF!$A:$A,"*" & $A29 & "*") <> 0, "Yes", "No") -> Yes | AB29: {=INDEX(S24_CF!H:H, MATCH("*" & $A29 & "*", S24_CF!$A:$A, 0))} -> Basic Two-Day [$2000.00]
